Workbook
Name __mtn1: '[1]<= 3 ans'!#REF!
Name __mtn1: '[1]<= 3 ans'!#REF!
Name __mtn1: '[1]<= 3 ans'!#REF!
Name __mtn1: '[1]<= 3 ans'!#REF!
Name __mtn1: '[1]<= 3 ans'!#REF!
Name __mtn1: '[1]<= 3 ans'!#REF!
Name __mtn1: '[1]<= 3 ans'!#REF!
Name __mtn1: '[1]<= 3 ans'!#REF!
Name __mtn1: '[1]<= 3 ans'!#REF!
Name __mtn1: '[1]<= 3 ans'!#REF!
Name __mtn3: #REF!
Name __mtn3: #REF!
Name __mtn3: #REF!
Name __mtn3: #REF!
Name __mtn3: #REF!
Name __mtn3: #REF!
Name __mtn3: #REF!
Name __mtn3: #REF!
Name __mtn3: #REF!
Name __mtn3: #REF!
Name _mtn1: '[1]<= 3 ans'!#REF!
Name _mtn1: '[1]<= 3 ans'!#REF!
Name _mtn1: '[1]<= 3 ans'!#REF!
Name _mtn1: '[1]<= 3 ans'!#REF!
Name _mtn1: '[1]<= 3 ans'!#REF!
Name _mtn1: '[1]<= 3 ans'!#REF!
Name _mtn1: '[1]<= 3 ans'!#REF!
Name _mtn1: '[1]<= 3 ans'!#REF!
Name _mtn1: '[1]<= 3 ans'!#REF!
Name _mtn1: '[1]<= 3 ans'!#REF!
Name _mtn3: #REF!
Name _mtn3: #REF!
Name _mtn3: #REF!
Name _mtn3: #REF!
Name _mtn3: #REF!
Name _mtn3: #REF!
Name _mtn3: #REF!
Name _mtn3: #REF!
Name _mtn3: #REF!
Name _mtn3: #REF!
Name accessoi: [2]fiche!$A$38
Name ANALYTIQUE: '[3]Liste immo'!$G$8:$G$19
Name AVANCEMENT: #REF!
Name AVANCEMENT: #REF!
Name AVANCEMENT: #REF!
Name AVANCEMENT: #REF!
Name AVANCEMENT: #REF!
Name AVANCEMENT: #REF!
Name AVANCEMENT: #REF!
Name AVANCEMENT: #REF!
Name AVANCEMENT: #REF!
Name AVANCEMENT: #REF!
Name BATIMENT: #REF!
Name BATIMENT: #REF!
Name BATIMENT: #REF!
Name BATIMENT: #REF!
Name BATIMENT: #REF!
Name BATIMENT: #REF!
Name BATIMENT: #REF!
Name BATIMENT: #REF!

Sheet Salaires
C3: SALAIRES
F4: 45596 | G4: 45626 | H4: 45657 | I4: 45688 | J4: 45716 | K4: 45747 | L4: 45777 | M4: 45808 | N4: 45838 | O4: 45869 | P4: 45900 | Q4: 45930
C5: RUBRIQUE | E5: TOTAL 2025/2026 | F5: 45961 | G5: 45991 | H5: 46022 | I5: 46053 | J5: 46081 | K5: 46112 | L5: 46142 | M5: 46173 | N5: 46203 | O5: 46234 | P5: 46265 | Q5: 46295
C7: A | E7: =SUM(F7:P7) -> 0
C8: B | E8: =SUM(F8:P8) -> 0
C9: C | E9: =SUM(F9:P9) -> 0
E10: =SUM(F10:P10) -> 0
E11: =SUM(F11:P11) -> 0
E12: =SUM(F12:P12) -> 0
E13: =SUM(F13:P13) -> 0
E14: =SUM(F14:P14) -> 0
E15: =SUM(F15:P15) -> 0
E16: =SUM(F16:P16) -> 0
E17: =SUM(F17:P17) -> 0
C19: CHARGES DE PERSONNEL | E19: =SUM(F19:P19) -> 0 | F19: =SUM(F7:F17) -> 0 | G19: =SUM(G7:G17) -> 0 | H19: =SUM(H7:H17) -> 0 | I19: =SUM(I7:I17) -> 0 | J19: =SUM(J7:J17) -> 0 | K19: =SUM(K7:K17) -> 0 | L19: =SUM(L7:L17) -> 0 | M19: =SUM(M7:M17) -> 0 | ... Q19: =SUM(Q7:Q17) -> 0
M22: =+L19-M19 -> 0

Sheet Enseignants
T3: Année scolaire : 2025/2026
C4: ETAT NOMINATIF DU PERSONNEL ENSEIGNANT
C5: (ELEMENTAIRE)
C7: N° | D7: Matricule | E7: Prénom (s) | F7: Nom | G7: Sexe | H7: Date de Naissance | I7: CNI | J7: Situation matrimoniale | K7: Corps | L7: Grade /Génération | M7: Diplôme académique | N7: Diplôme prof. | O7: Date d’entrée dans l’enseignement | P7: Spécialité | Q7: Fonction | R7: Date de prise de service dans l’établissement | S7: Cours tenu(s) | T7: Type classe | U7: Effectifs | V7: Emargement
B8: =+E8&" "&F8 | C8: 1 | D8: 001
B9: =+E9&" "&F9 | C9: =+C8+1 -> 2 | D9: =TEXT(D8+1,"000") -> 002
B10: =+E10&" "&F10 | C10: =+C9+1 -> 3 | D10: =TEXT(D9+1,"000") -> 003
B11: =+E11&" "&F11 | C11: =+C10+1 -> 4 | D11: =TEXT(D10+1,"000") -> 004
B12: =+E12&" "&F12 | C12: =+C11+1 -> 5 | D12: =TEXT(D11+1,"000") -> 005
B13: =+E13&" "&F13 | C13: =+C12+1 -> 6 | D13: =TEXT(D12+1,"000") -> 006
B14: =+E14&" "&F14 | C14: =+C13+1 -> 7 | D14: =TEXT(D13+1,"000") -> 007
B15: =+E15&" "&F15 | C15: =+C14+1 -> 8 | D15: =TEXT(D14+1,"000") -> 008
B16: =+E16&" "&F16 | C16: =+C15+1 -> 9 | D16: =TEXT(D15+1,"000") -> 009
B17: =+E17&" "&F17 | C17: =+C16+1 -> 10
B18: =+E18&" "&F18 | C18: =+C17+1 -> 11

Sheet GARDERIE
D2: Gestion des inscriptions : 2025-2026
D4: Ce feuillet vous permet de suivre le processus d'inscription de chaque élève en début d'année.
D6: TOTAL INSCRIPTION | M6: MENSUALITE | W6: CANTINE | AG6: RENFORCE+ | AQ6: UNIFORME
H7: Inscription payée | I7: Montant inscription | J7: Uniforme | K7: Assurance | L7: APE | M7: 45961 | N7: 45991 | O7: 46022 | P7: 46053 | Q7: 46081 | R7: 46112 | S7: 46142 | T7: 46173 | U7: 46203 | W7: 45961 | X7: 45991 | Y7: 46022 | Z7: 46053 | AA7: 46081 | AB7: 46112 | AC7: 46142 | AD7: 46173 | AE7: 46203 | AG7: 45961 | AH7: 45991 | AI7: 46022 | AJ7: 46053 | AK7: 46081 | AL7: 46112 | AM7: 46142 | AN7: 46173 | AO7: 46203 | AQ7: 45961 | AR7: 45991 | AS7: 46022 | AT7: 46053 | AU7: 46081 | AV7: 46112 | AW7: 46142 | AX7: 46173 | AY7: 46203
C8: N | D8: Prénom | E8: Nom | F8: Classe | G8: Date de naisssance | H8: =+SUM(H9:H41) -> 0 | I8: =+SUM(I9:I41) -> 0 | J8: =+SUM(J9:J41) -> 0 | K8: =+SUM(K9:K41) -> 0 | L8: =+SUM(L9:L41) -> 0 | M8: =+SUM(M9:M41) -> 0 | N8: =+SUM(N9:N41) -> 0 | O8: =+SUM(O9:O41) -> 0 | ... U8: =+SUM(U9:U41) -> 0 | W8: =+SUM(W9:W41) -> 0 | X8: =+SUM(X9:X41) -> 0 | Y8: =+SUM(Y9:Y41) -> 0 | Z8: =+SUM(Z9:Z41) -> 0 | AA8: =+SUM(AA9:AA41) -> 0 | AB8: =+SUM(AB9:AB41) -> 0 | AC8: =+SUM(AC9:AC41) -> 0 | AD8: =+SUM(AD9:AD41) -> 0 | AE8: =+SUM(AE9:AE41) -> 0 | AG8: =+SUM(AG9:AG41) -> 0 | AH8: =+SUM(AH9:AH41) -> 0 | AI8: =+SUM(AI9:AI41) -> 0 | AJ8: =+SUM(AJ9:AJ41) -> 0 | AK8: =+SUM(AK9:AK41) -> 0 | AL8: =+SUM(AL9:AL41) -> 0 | AM8: =+SUM(AM9:AM41) -> 0 | AN8: =+SUM(AN9:AN41) -> 0 | AO8: =+SUM(AO9:AO41) -> 0 | AQ8: =+SUM(AQ9:AQ41) -> 0 | AR8: =+SUM(AR9:AR41) -> 1 | AS8: =+SUM(AS9:AS41) -> 1 | AT8: =+SUM(AT9:AT41) -> 1 | AU8: =+SUM(AU9:AU41) -> 1 | AV8: =+SUM(AV9:AV41) -> 1 | AW8: =+SUM(AW9:AW41) -> 1 | AX8: =+SUM(AX9:AX41) -> 1 | AY8: =+SUM(AY9:AY41) -> 1
C9: 1 | AR9: 1 | AS9: 1 | AT9: 1 | AU9: 1 | AV9: 1 | AW9: 1 | AX9: 1 | AY9: 1
C10: =+C9+1 -> 2
C11: =+C10+1 -> 3
C12: =+C11+1 -> 4
C13: =+C12+1 -> 5
C14: =+C13+1 -> 6
C15: =+C14+1 -> 7
C16: =+C15+1 -> 8
C17: =+C16+1 -> 9
C18: =+C17+1 -> 10
C19: =+C18+1 -> 11
C20: =+C19+1 -> 12
C21: =+C20+1 -> 13
... C40: =+C39+1 -> 32

Sheet PS
D2: Gestion des inscriptions : 2025-2026
D4: Ce feuillet vous permet de suivre le processus d'inscription de chaque élève en début d'année.
D6: TOTAL INSCRIPTION | M6: MENSUALITE | W6: CANTINE | AG6: RENFORCE+ | AQ6: UNIFORME
H7: Inscription payée | I7: Montant inscription | J7: Uniforme | K7: Assurance | L7: APE | M7: 45961 | N7: 45991 | O7: 46022 | P7: 46053 | Q7: 46081 | R7: 46112 | S7: 46142 | T7: 46173 | U7: 46203 | W7: 45961 | X7: 45991 | Y7: 46022 | Z7: 46053 | AA7: 46081 | AB7: 46112 | AC7: 46142 | AD7: 46173 | AE7: 46203 | AG7: 45961 | AH7: 45991 | AI7: 46022 | AJ7: 46053 | AK7: 46081 | AL7: 46112 | AM7: 46142 | AN7: 46173 | AO7: 46203 | AQ7: 45961 | AR7: 45991 | AS7: 46022 | AT7: 46053 | AU7: 46081 | AV7: 46112 | AW7: 46142 | AX7: 46173 | AY7: 46203
C8: N | D8: Prénom | E8: Nom | F8: Classe | G8: Date de naisssance | H8: =+SUM(H9:H41) -> 0 | I8: =+SUM(I9:I41) -> 0 | J8: =+SUM(J9:J41) -> 0 | K8: =+SUM(K9:K41) -> 0 | L8: =+SUM(L9:L41) -> 0 | M8: =+SUM(M9:M29) -> 0 | N8: =+SUM(N9:N29) -> 0 | O8: =+SUM(O9:O29) -> 0 | P8: =+SUM(P9:P29) -> 0 | Q8: =+SUM(Q9:Q29) -> 0 | R8: =+SUM(R9:R29) -> 0 | S8: =+SUM(S9:S29) -> 0 | T8: =+SUM(T9:T29) -> 0 | U8: =+SUM(U9:U29) -> 0 | W8: =+SUM(W9:W29) -> 0 | X8: =+SUM(X9:X29) -> 0 | Y8: =+SUM(Y9:Y29) -> 0 | Z8: =+SUM(Z9:Z29) -> 0 | AA8: =+SUM(AA9:AA29) -> 0 | AB8: =+SUM(AB9:AB29) -> 0 | AC8: =+SUM(AC9:AC29) -> 0 | AD8: =+SUM(AD9:AD29) -> 0 | AE8: =+SUM(AE9:AE29) -> 0 | AG8: =+SUM(AG9:AG29) -> 0 | AH8: =+SUM(AH9:AH29) -> 0 | AI8: =+SUM(AI9:AI29) -> 0 | AJ8: =+SUM(AJ9:AJ29) -> 0 | AK8: =+SUM(AK9:AK29) -> 0 | AL8: =+SUM(AL9:AL29) -> 0 | AM8: =+SUM(AM9:AM29) -> 0 | AN8: =+SUM(AN9:AN29) -> 0 | AO8: =+SUM(AO9:AO29) -> 0 | AQ8: =+SUM(AQ9:AQ29) -> 0 | AR8: =+SUM(AR9:AR29) -> 1 | AS8: =+SUM(AS9:AS29) -> 1 | AT8: =+SUM(AT9:AT29) -> 1 | AU8: =+SUM(AU9:AU29) -> 1 | AV8: =+SUM(AV9:AV29) -> 1 | AW8: =+SUM(AW9:AW29) -> 1 | AX8: =+SUM(AX9:AX29) -> 1 | AY8: =+SUM(AY9:AY29) -> 1
C9: 1 | AR9: 1 | AS9: 1 | AT9: 1 | AU9: 1 | AV9: 1 | AW9: 1 | AX9: 1 | AY9: 1
C10: =+C9+1 -> 2
C11: =+C10+1 -> 3
C12: =+C11+1 -> 4
C13: =+C12+1 -> 5
C14: =+C13+1 -> 6
C15: =+C14+1 -> 7
C16: =+C15+1 -> 8
C17: =+C16+1 -> 9
C18: =+C17+1 -> 10
C19: =+C18+1 -> 11
C20: =+C19+1 -> 12
C21: =+C20+1 -> 13
... C41: =+C40+1 -> 33

Sheet MS
D2: Gestion des inscriptions : 2025-2026
D4: Ce feuillet vous permet de suivre le processus d'inscription de chaque élève en début d'année.
D6: TOTAL INSCRIPTION | M6: MENSUALITE | W6: CANTINE | AG6: RENFORCE+ | AQ6: UNIFORME
H7: Inscription payée | I7: Montant inscription | J7: Uniforme | K7: Assurance | L7: APE | M7: 45961 | N7: 45991 | O7: 46022 | P7: 46053 | Q7: 46081 | R7: 46112 | S7: 46142 | T7: 46173 | U7: 46203 | W7: 45961 | X7: 45991 | Y7: 46022 | Z7: 46053 | AA7: 46081 | AB7: 46112 | AC7: 46142 | AD7: 46173 | AE7: 46203 | AG7: 45961 | AH7: 45991 | AI7: 46022 | AJ7: 46053 | AK7: 46081 | AL7: 46112 | AM7: 46142 | AN7: 46173 | AO7: 46203 | AQ7: 45961 | AR7: 45991 | AS7: 46022 | AT7: 46053 | AU7: 46081 | AV7: 46112 | AW7: 46142 | AX7: 46173 | AY7: 46203
C8: N | D8: Prénom | E8: Nom | F8: Classe | G8: Date de naisssance | H8: =+SUM(H9:H41) -> 0 | I8: =+SUM(I9:I41) -> 0 | J8: =+SUM(J9:J41) -> 0 | K8: =+SUM(K9:K41) -> 0 | L8: =+SUM(L9:L41) -> 0 | M8: =+SUM(M9:M29) -> 0 | N8: =+SUM(N9:N29) -> 0 | O8: =+SUM(O9:O29) -> 0 | P8: =+SUM(P9:P29) -> 0 | Q8: =+SUM(Q9:Q29) -> 0 | R8: =+SUM(R9:R29) -> 0 | S8: =+SUM(S9:S29) -> 0 | T8: =+SUM(T9:T29) -> 0 | U8: =+SUM(U9:U29) -> 0 | W8: =+SUM(W9:W29) -> 0 | X8: =+SUM(X9:X29) -> 0 | Y8: =+SUM(Y9:Y29) -> 0 | Z8: =+SUM(Z9:Z29) -> 0 | AA8: =+SUM(AA9:AA29) -> 0 | AB8: =+SUM(AB9:AB29) -> 0 | AC8: =+SUM(AC9:AC29) -> 0 | AD8: =+SUM(AD9:AD29) -> 0 | AE8: =+SUM(AE9:AE29) -> 0 | AG8: =+SUM(AG9:AG29) -> 0 | AH8: =+SUM(AH9:AH29) -> 0 | AI8: =+SUM(AI9:AI29) -> 0 | AJ8: =+SUM(AJ9:AJ29) -> 0 | AK8: =+SUM(AK9:AK29) -> 0 | AL8: =+SUM(AL9:AL29) -> 0 | AM8: =+SUM(AM9:AM29) -> 0 | AN8: =+SUM(AN9:AN29) -> 0 | AO8: =+SUM(AO9:AO29) -> 0 | AQ8: =+SUM(AQ9:AQ29) -> 0 | AR8: =+SUM(AR9:AR29) -> 0 | AS8: =+SUM(AS9:AS29) -> 0 | AT8: =+SUM(AT9:AT29) -> 0 | AU8: =+SUM(AU9:AU29) -> 0 | AV8: =+SUM(AV9:AV29) -> 0 | AW8: =+SUM(AW9:AW29) -> 0 | AX8: =+SUM(AX9:AX29) -> 0 | AY8: =+SUM(AY9:AY29) -> 0
C9: 1
C10: =+C9+1 -> 2
C11: =+C10+1 -> 3
C12: =+C11+1 -> 4
C13: =+C12+1 -> 5
C14: =+C13+1 -> 6
C15: =+C14+1 -> 7
C16: =+C15+1 -> 8
C17: =+C16+1 -> 9
C18: =+C17+1 -> 10
C19: =+C18+1 -> 11
C20: =+C19+1 -> 12
C21: =+C20+1 -> 13
... C28: =+C27+1 -> 20

Sheet GS
D2: Gestion des inscriptions : 2025-2026
D4: Ce feuillet vous permet de suivre le processus d'inscription de chaque élève en début d'année.
D6: TOTAL INSCRIPTION | M6: MENSUALITE | W6: CANTINE | AG6: RENFORCE+ | AQ6: UNIFORME
H7: Inscription payée | I7: Montant inscription | J7: Uniforme | K7: Assurance | L7: APE | M7: 45961 | N7: 45991 | O7: 46022 | P7: 46053 | Q7: 46081 | R7: 46112 | S7: 46142 | T7: 46173 | U7: 46203 | W7: 45961 | X7: 45991 | Y7: 46022 | Z7: 46053 | AA7: 46081 | AB7: 46112 | AC7: 46142 | AD7: 46173 | AE7: 46203 | AG7: 45961 | AH7: 45991 | AI7: 46022 | AJ7: 46053 | AK7: 46081 | AL7: 46112 | AM7: 46142 | AN7: 46173 | AO7: 46203 | AQ7: 45961 | AR7: 45991 | AS7: 46022 | AT7: 46053 | AU7: 46081 | AV7: 46112 | AW7: 46142 | AX7: 46173 | AY7: 46203
C8: N | D8: Prénom | E8: Nom | F8: Classe | G8: Date de naisssance | H8: =+SUM(H9:H41) -> 0 | I8: =+SUM(I9:I41) -> 0 | J8: =+SUM(J9:J41) -> 0 | K8: =+SUM(K9:K41) -> 0 | L8: =+SUM(L9:L41) -> 0 | M8: =+SUM(M9:M29) -> 0 | N8: =+SUM(N9:N29) -> 0 | O8: =+SUM(O9:O29) -> 0 | P8: =+SUM(P9:P29) -> 0 | Q8: =+SUM(Q9:Q29) -> 0 | R8: =+SUM(R9:R29) -> 0 | S8: =+SUM(S9:S29) -> 0 | T8: =+SUM(T9:T29) -> 0 | U8: =+SUM(U9:U29) -> 0 | W8: =+SUM(W9:W29) -> 0 | X8: =+SUM(X9:X29) -> 0 | Y8: =+SUM(Y9:Y29) -> 0 | Z8: =+SUM(Z9:Z29) -> 0 | AA8: =+SUM(AA9:AA29) -> 0 | AB8: =+SUM(AB9:AB29) -> 0 | AC8: =+SUM(AC9:AC29) -> 0 | AD8: =+SUM(AD9:AD29) -> 0 | AE8: =+SUM(AE9:AE29) -> 0 | AG8: =+SUM(AG9:AG29) -> 0 | AH8: =+SUM(AH9:AH29) -> 0 | AI8: =+SUM(AI9:AI29) -> 0 | AJ8: =+SUM(AJ9:AJ29) -> 0 | AK8: =+SUM(AK9:AK29) -> 0 | AL8: =+SUM(AL9:AL29) -> 0 | AM8: =+SUM(AM9:AM29) -> 0 | AN8: =+SUM(AN9:AN29) -> 0 | AO8: =+SUM(AO9:AO29) -> 0 | AQ8: =+SUM(AQ9:AQ29) -> 0 | AR8: =+SUM(AR9:AR29) -> 0 | AS8: =+SUM(AS9:AS29) -> 0 | AT8: =+SUM(AT9:AT29) -> 0 | AU8: =+SUM(AU9:AU29) -> 0 | AV8: =+SUM(AV9:AV29) -> 0 | AW8: =+SUM(AW9:AW29) -> 0 | AX8: =+SUM(AX9:AX29) -> 0 | AY8: =+SUM(AY9:AY29) -> 0
C9: 1
C10: =+C9+1 -> 2
C11: =+C10+1 -> 3
C12: =+C11+1 -> 4
C13: =+C12+1 -> 5
C14: =+C13+1 -> 6
C15: =+C14+1 -> 7
C16: =+C15+1 -> 8
C17: =+C16+1 -> 9
C18: =+C17+1 -> 10
C19: =+C18+1 -> 11
C20: =+C19+1 -> 12
C21: =+C20+1 -> 13
... C28: =+C27+1 -> 20

Sheet CI
I1: ;
D2: Gestion des inscriptions : 2025-2026
D4: Ce feuillet vous permet de suivre le processus d'inscription de chaque élève en début d'année.
D6: TOTAL INSCRIPTION | M6: MENSUALITE | W6: CANTINE | AG6: RENFORCE+ | AQ6: UNIFORME
H7: Inscription payée | I7: Montant inscription | J7: Uniforme | K7: Assurance | L7: APE | M7: 45961 | N7: 45991 | O7: 46022 | P7: 46053 | Q7: 46081 | R7: 46112 | S7: 46142 | T7: 46173 | U7: 46203 | W7: 45961 | X7: 45991 | Y7: 46022 | Z7: 46053 | AA7: 46081 | AB7: 46112 | AC7: 46142 | AD7: 46173 | AE7: 46203 | AG7: 45961 | AH7: 45991 | AI7: 46022 | AJ7: 46053 | AK7: 46081 | AL7: 46112 | AM7: 46142 | AN7: 46173 | AO7: 46203 | AQ7: 45961 | AR7: 45991 | AS7: 46022 | AT7: 46053 | AU7: 46081 | AV7: 46112 | AW7: 46142 | AX7: 46173 | AY7: 46203
C8: N | D8: Prénom | E8: Nom | F8: Classe | G8: Date de naisssance | H8: =+SUM(H9:H41) -> 0 | I8: =+SUM(I9:I41) -> 0 | J8: =+SUM(J9:J41) -> 0 | K8: =+SUM(K9:K41) -> 0 | L8: =+SUM(L9:L41) -> 0 | M8: =+SUM(M9:M29) -> 0 | N8: =+SUM(N9:N29) -> 0 | O8: =+SUM(O9:O29) -> 0 | P8: =+SUM(P9:P29) -> 0 | Q8: =+SUM(Q9:Q29) -> 0 | R8: =+SUM(R9:R29) -> 0 | S8: =+SUM(S9:S29) -> 0 | T8: =+SUM(T9:T29) -> 0 | U8: =+SUM(U9:U29) -> 0 | W8: =+SUM(W9:W29) -> 0 | X8: =+SUM(X9:X29) -> 0 | Y8: =+SUM(Y9:Y29) -> 0 | Z8: =+SUM(Z9:Z29) -> 0 | AA8: =+SUM(AA9:AA29) -> 0 | AB8: =+SUM(AB9:AB29) -> 0 | AC8: =+SUM(AC9:AC29) -> 0 | AD8: =+SUM(AD9:AD29) -> 0 | AE8: =+SUM(AE9:AE29) -> 0 | AG8: =+SUM(AG9:AG29) -> 0 | AH8: =+SUM(AH9:AH29) -> 0 | AI8: =+SUM(AI9:AI29) -> 0 | AJ8: =+SUM(AJ9:AJ29) -> 0 | AK8: =+SUM(AK9:AK29) -> 0 | AL8: =+SUM(AL9:AL29) -> 0 | AM8: =+SUM(AM9:AM29) -> 0 | AN8: =+SUM(AN9:AN29) -> 0 | AO8: =+SUM(AO9:AO29) -> 0 | AQ8: =+SUM(AQ9:AQ29) -> 0 | AR8: =+SUM(AR9:AR29) -> 0 | AS8: =+SUM(AS9:AS29) -> 0 | AT8: =+SUM(AT9:AT29) -> 0 | AU8: =+SUM(AU9:AU29) -> 0 | AV8: =+SUM(AV9:AV29) -> 0 | AW8: =+SUM(AW9:AW29) -> 0 | AX8: =+SUM(AX9:AX29) -> 0 | AY8: =+SUM(AY9:AY29) -> 0
C9: 1
C10: =+C9+1 -> 2
C11: =+C10+1 -> 3
C12: =+C11+1 -> 4
C13: =+C12+1 -> 5
C14: =+C13+1 -> 6
C15: =+C14+1 -> 7
C16: =+C15+1 -> 8
C17: =+C16+1 -> 9
C18: =+C17+1 -> 10
C19: =+C18+1 -> 11
C20: =+C19+1 -> 12
C21: =+C20+1 -> 13
... C28: =+C27+1 -> 20

Sheet CP
D2: Gestion des inscriptions : 2025-2026
D4: Ce feuillet vous permet de suivre le processus d'inscription de chaque élève en début d'année.
D6: TOTAL INSCRIPTION | M6: MENSUALITE | W6: CANTINE | AG6: RENFORCE+ | AQ6: UNIFORME
H7: Inscription payée | I7: Montant inscription | J7: Uniforme | K7: Assurance | L7: APE | M7: 45961 | N7: 45991 | O7: 46022 | P7: 46053 | Q7: 46081 | R7: 46112 | S7: 46142 | T7: 46173 | U7: 46203 | W7: 45961 | X7: 45991 | Y7: 46022 | Z7: 46053 | AA7: 46081 | AB7: 46112 | AC7: 46142 | AD7: 46173 | AE7: 46203 | AG7: 45961 | AH7: 45991 | AI7: 46022 | AJ7: 46053 | AK7: 46081 | AL7: 46112 | AM7: 46142 | AN7: 46173 | AO7: 46203 | AQ7: 45961 | AR7: 45991 | AS7: 46022 | AT7: 46053 | AU7: 46081 | AV7: 46112 | AW7: 46142 | AX7: 46173 | AY7: 46203
C8: N | D8: Prénom | E8: Nom | F8: Classe | G8: Date de naisssance | H8: =+SUM(H9:H41) -> 0 | I8: =+SUM(I9:I41) -> 0 | J8: =+SUM(J9:J41) -> 0 | K8: =+SUM(K9:K41) -> 0 | L8: =+SUM(L9:L41) -> 0 | M8: =+SUM(M9:M29) -> 0 | N8: =+SUM(N9:N29) -> 0 | O8: =+SUM(O9:O29) -> 0 | P8: =+SUM(P9:P29) -> 0 | Q8: =+SUM(Q9:Q29) -> 0 | R8: =+SUM(R9:R29) -> 0 | S8: =+SUM(S9:S29) -> 0 | T8: =+SUM(T9:T29) -> 0 | U8: =+SUM(U9:U29) -> 0 | W8: =+SUM(W9:W29) -> 0 | X8: =+SUM(X9:X29) -> 0 | Y8: =+SUM(Y9:Y29) -> 0 | Z8: =+SUM(Z9:Z29) -> 0 | AA8: =+SUM(AA9:AA29) -> 0 | AB8: =+SUM(AB9:AB29) -> 0 | AC8: =+SUM(AC9:AC29) -> 0 | AD8: =+SUM(AD9:AD29) -> 0 | AE8: =+SUM(AE9:AE29) -> 0 | AG8: =+SUM(AG9:AG29) -> 0 | AH8: =+SUM(AH9:AH29) -> 0 | AI8: =+SUM(AI9:AI29) -> 0 | AJ8: =+SUM(AJ9:AJ29) -> 0 | AK8: =+SUM(AK9:AK29) -> 0 | AL8: =+SUM(AL9:AL29) -> 0 | AM8: =+SUM(AM9:AM29) -> 0 | AN8: =+SUM(AN9:AN29) -> 0 | AO8: =+SUM(AO9:AO29) -> 0 | AQ8: =+SUM(AQ9:AQ29) -> 0 | AR8: =+SUM(AR9:AR29) -> 0 | AS8: =+SUM(AS9:AS29) -> 0 | AT8: =+SUM(AT9:AT29) -> 0 | AU8: =+SUM(AU9:AU29) -> 0 | AV8: =+SUM(AV9:AV29) -> 0 | AW8: =+SUM(AW9:AW29) -> 0 | AX8: =+SUM(AX9:AX29) -> 0 | AY8: =+SUM(AY9:AY29) -> 0
C9: 1
C10: =+C9+1 -> 2
C11: =+C10+1 -> 3
C12: =+C11+1 -> 4
C13: =+C12+1 -> 5
C14: =+C13+1 -> 6
C15: =+C14+1 -> 7
C16: =+C15+1 -> 8
C17: =+C16+1 -> 9
C18: =+C17+1 -> 10
C19: =+C18+1 -> 11
C20: =+C19+1 -> 12
C21: =+C20+1 -> 13
... C28: =+C27+1 -> 20

Sheet CE1
D2: Gestion des inscriptions : 2025-2026
D4: Ce feuillet vous permet de suivre le processus d'inscription de chaque élève en début d'année.
D6: TOTAL INSCRIPTION | M6: MENSUALITE | W6: CANTINE | AG6: RENFORCE+ | AQ6: UNIFORME
H7: Inscription payée | I7: Montant inscription | J7: Uniforme | K7: Assurance | L7: APE | M7: 45961 | N7: 45991 | O7: 46022 | P7: 46053 | Q7: 46081 | R7: 46112 | S7: 46142 | T7: 46173 | U7: 46203 | W7: 45961 | X7: 45991 | Y7: 46022 | Z7: 46053 | AA7: 46081 | AB7: 46112 | AC7: 46142 | AD7: 46173 | AE7: 46203 | AG7: 45961 | AH7: 45991 | AI7: 46022 | AJ7: 46053 | AK7: 46081 | AL7: 46112 | AM7: 46142 | AN7: 46173 | AO7: 46203 | AQ7: 45961 | AR7: 45991 | AS7: 46022 | AT7: 46053 | AU7: 46081 | AV7: 46112 | AW7: 46142 | AX7: 46173 | AY7: 46203
C8: N | D8: Prénom | E8: Nom | F8: Classe | G8: Date de naisssance | H8: =+SUM(H9:H41) -> 0 | I8: =+SUM(I9:I41) -> 0 | J8: =+SUM(J9:J41) -> 0 | K8: =+SUM(K9:K41) -> 0 | L8: =+SUM(L9:L41) -> 0 | M8: =+SUM(M9:M29) -> 0 | N8: =+SUM(N9:N29) -> 0 | O8: =+SUM(O9:O29) -> 0 | P8: =+SUM(P9:P29) -> 0 | Q8: =+SUM(Q9:Q29) -> 0 | R8: =+SUM(R9:R29) -> 0 | S8: =+SUM(S9:S29) -> 0 | T8: =+SUM(T9:T29) -> 0 | U8: =+SUM(U9:U29) -> 0 | W8: =+SUM(W9:W29) -> 0 | X8: =+SUM(X9:X29) -> 0 | Y8: =+SUM(Y9:Y29) -> 0 | Z8: =+SUM(Z9:Z29) -> 0 | AA8: =+SUM(AA9:AA29) -> 0 | AB8: =+SUM(AB9:AB29) -> 0 | AC8: =+SUM(AC9:AC29) -> 0 | AD8: =+SUM(AD9:AD29) -> 0 | AE8: =+SUM(AE9:AE29) -> 0 | AG8: =+SUM(AG9:AG29) -> 0 | AH8: =+SUM(AH9:AH29) -> 0 | AI8: =+SUM(AI9:AI29) -> 0 | AJ8: =+SUM(AJ9:AJ29) -> 0 | AK8: =+SUM(AK9:AK29) -> 0 | AL8: =+SUM(AL9:AL29) -> 0 | AM8: =+SUM(AM9:AM29) -> 0 | AN8: =+SUM(AN9:AN29) -> 0 | AO8: =+SUM(AO9:AO29) -> 0 | AQ8: =+SUM(AQ9:AQ29) -> 0 | AR8: =+SUM(AR9:AR29) -> 0 | AS8: =+SUM(AS9:AS29) -> 0 | AT8: =+SUM(AT9:AT29) -> 0 | AU8: =+SUM(AU9:AU29) -> 0 | AV8: =+SUM(AV9:AV29) -> 0 | AW8: =+SUM(AW9:AW29) -> 0 | AX8: =+SUM(AX9:AX29) -> 0 | AY8: =+SUM(AY9:AY29) -> 0
C9: 1
C10: =+C9+1 -> 2
C11: =+C10+1 -> 3
C12: =+C11+1 -> 4
C13: =+C12+1 -> 5
C14: =+C13+1 -> 6
C15: =+C14+1 -> 7
C16: =+C15+1 -> 8
C17: =+C16+1 -> 9
C18: =+C17+1 -> 10
C19: =+C18+1 -> 11
C20: =+C19+1 -> 12
C21: =+C20+1 -> 13
... C28: =+C27+1 -> 20

Sheet CE2
D2: Gestion des inscriptions : 2025-2026
D4: Ce feuillet vous permet de suivre le processus d'inscription de chaque élève en début d'année.
D6: TOTAL INSCRIPTION | M6: MENSUALITE | W6: CANTINE | AG6: RENFORCE+ | AQ6: UNIFORME
H7: Inscription payée | I7: Montant inscription | J7: Uniforme | K7: Assurance | L7: APE | M7: 45961 | N7: 45991 | O7: 46022 | P7: 46053 | Q7: 46081 | R7: 46112 | S7: 46142 | T7: 46173 | U7: 46203 | W7: 45961 | X7: 45991 | Y7: 46022 | Z7: 46053 | AA7: 46081 | AB7: 46112 | AC7: 46142 | AD7: 46173 | AE7: 46203 | AG7: 45961 | AH7: 45991 | AI7: 46022 | AJ7: 46053 | AK7: 46081 | AL7: 46112 | AM7: 46142 | AN7: 46173 | AO7: 46203 | AQ7: 45961 | AR7: 45991 | AS7: 46022 | AT7: 46053 | AU7: 46081 | AV7: 46112 | AW7: 46142 | AX7: 46173 | AY7: 46203
C8: N | D8: Prénom | E8: Nom | F8: Classe | G8: Date de naisssance | H8: =+SUM(H9:H41) -> 0 | I8: =+SUM(I9:I41) -> 0 | J8: =+SUM(J9:J41) -> 0 | K8: =+SUM(K9:K41) -> 0 | L8: =+SUM(L9:L41) -> 0 | M8: =+SUM(M9:M29) -> 0 | N8: =+SUM(N9:N29) -> 0 | O8: =+SUM(O9:O29) -> 0 | P8: =+SUM(P9:P29) -> 0 | Q8: =+SUM(Q9:Q29) -> 0 | R8: =+SUM(R9:R29) -> 0 | S8: =+SUM(S9:S29) -> 0 | T8: =+SUM(T9:T29) -> 0 | U8: =+SUM(U9:U29) -> 0 | W8: =+SUM(W9:W29) -> 0 | X8: =+SUM(X9:X29) -> 0 | Y8: =+SUM(Y9:Y29) -> 0 | Z8: =+SUM(Z9:Z29) -> 0 | AA8: =+SUM(AA9:AA29) -> 0 | AB8: =+SUM(AB9:AB29) -> 0 | AC8: =+SUM(AC9:AC29) -> 0 | AD8: =+SUM(AD9:AD29) -> 0 | AE8: =+SUM(AE9:AE29) -> 0 | AG8: =+SUM(AG9:AG29) -> 0 | AH8: =+SUM(AH9:AH29) -> 0 | AI8: =+SUM(AI9:AI29) -> 0 | AJ8: =+SUM(AJ9:AJ29) -> 0 | AK8: =+SUM(AK9:AK29) -> 0 | AL8: =+SUM(AL9:AL29) -> 0 | AM8: =+SUM(AM9:AM29) -> 0 | AN8: =+SUM(AN9:AN29) -> 0 | AO8: =+SUM(AO9:AO29) -> 0 | AQ8: =+SUM(AQ9:AQ29) -> 0 | AR8: =+SUM(AR9:AR29) -> 0 | AS8: =+SUM(AS9:AS29) -> 0 | AT8: =+SUM(AT9:AT29) -> 0 | AU8: =+SUM(AU9:AU29) -> 0 | AV8: =+SUM(AV9:AV29) -> 0 | AW8: =+SUM(AW9:AW29) -> 0 | AX8: =+SUM(AX9:AX29) -> 0 | AY8: =+SUM(AY9:AY29) -> 0
C9: 1
C10: =+C9+1 -> 2
C11: =+C10+1 -> 3
C12: =+C11+1 -> 4
C13: =+C12+1 -> 5
C14: =+C13+1 -> 6
C15: =+C14+1 -> 7
C16: =+C15+1 -> 8
C17: =+C16+1 -> 9
C18: =+C17+1 -> 10
C19: =+C18+1 -> 11
C20: =+C19+1 -> 12
C21: =+C20+1 -> 13
... C28: =+C27+1 -> 20

Sheet CM1
D2: Gestion des inscriptions : 2025-2026
D4: Ce feuillet vous permet de suivre le processus d'inscription de chaque élève en début d'année.
D6: TOTAL INSCRIPTION | M6: MENSUALITE | W6: CANTINE | AG6: RENFORCE+ | AQ6: UNIFORME
H7: Inscription payée | I7: Montant inscription | J7: Uniforme | K7: Assurance | L7: APE | M7: 45961 | N7: 45991 | O7: 46022 | P7: 46053 | Q7: 46081 | R7: 46112 | S7: 46142 | T7: 46173 | U7: 46203 | W7: 45961 | X7: 45991 | Y7: 46022 | Z7: 46053 | AA7: 46081 | AB7: 46112 | AC7: 46142 | AD7: 46173 | AE7: 46203 | AG7: 45961 | AH7: 45991 | AI7: 46022 | AJ7: 46053 | AK7: 46081 | AL7: 46112 | AM7: 46142 | AN7: 46173 | AO7: 46203 | AQ7: 45961 | AR7: 45991 | AS7: 46022 | AT7: 46053 | AU7: 46081 | AV7: 46112 | AW7: 46142 | AX7: 46173 | AY7: 46203
C8: N | D8: Prénom | E8: Nom | F8: Classe | G8: Date de naisssance | H8: =+SUM(H9:H41) -> 0 | I8: =+SUM(I9:I41) -> 0 | J8: =+SUM(J9:J41) -> 0 | K8: =+SUM(K9:K41) -> 0 | L8: =+SUM(L9:L41) -> 0 | M8: =+SUM(M9:M29) -> 0 | N8: =+SUM(N9:N29) -> 0 | O8: =+SUM(O9:O29) -> 0 | P8: =+SUM(P9:P29) -> 0 | Q8: =+SUM(Q9:Q29) -> 0 | R8: =+SUM(R9:R29) -> 0 | S8: =+SUM(S9:S29) -> 0 | T8: =+SUM(T9:T29) -> 0 | U8: =+SUM(U9:U29) -> 0 | W8: =+SUM(W9:W29) -> 0 | X8: =+SUM(X9:X29) -> 0 | Y8: =+SUM(Y9:Y29) -> 0 | Z8: =+SUM(Z9:Z29) -> 0 | AA8: =+SUM(AA9:AA29) -> 0 | AB8: =+SUM(AB9:AB29) -> 0 | AC8: =+SUM(AC9:AC29) -> 0 | AD8: =+SUM(AD9:AD29) -> 0 | AE8: =+SUM(AE9:AE29) -> 0 | AG8: =+SUM(AG9:AG29) -> 0 | AH8: =+SUM(AH9:AH29) -> 0 | AI8: =+SUM(AI9:AI29) -> 0 | AJ8: =+SUM(AJ9:AJ29) -> 0 | AK8: =+SUM(AK9:AK29) -> 0 | AL8: =+SUM(AL9:AL29) -> 0 | AM8: =+SUM(AM9:AM29) -> 0 | AN8: =+SUM(AN9:AN29) -> 0 | AO8: =+SUM(AO9:AO29) -> 0 | AQ8: =+SUM(AQ9:AQ29) -> 0 | AR8: =+SUM(AR9:AR29) -> 0 | AS8: =+SUM(AS9:AS29) -> 0 | AT8: =+SUM(AT9:AT29) -> 0 | AU8: =+SUM(AU9:AU29) -> 0 | AV8: =+SUM(AV9:AV29) -> 0 | AW8: =+SUM(AW9:AW29) -> 0 | AX8: =+SUM(AX9:AX29) -> 0 | AY8: =+SUM(AY9:AY29) -> 0
C9: 1
C10: =+C9+1 -> 2
C11: =+C10+1 -> 3
C12: =+C11+1 -> 4
C13: =+C12+1 -> 5
C14: =+C13+1 -> 6
C15: =+C14+1 -> 7
C16: =+C15+1 -> 8
C17: =+C16+1 -> 9
C18: =+C17+1 -> 10
C19: =+C18+1 -> 11
C20: =+C19+1 -> 12
C21: =+C20+1 -> 13
... C28: =+C27+1 -> 20

Sheet CM2
D2: Gestion des inscriptions : 2025-2026
D4: Ce feuillet vous permet de suivre le processus d'inscription de chaque élève en début d'année.
D6: TOTAL INSCRIPTION | M6: MENSUALITE | W6: CANTINE | AG6: RENFORCE+ | AQ6: UNIFORME
H7: Inscription payée | I7: Montant inscription | J7: Uniforme | K7: Assurance | L7: APE | M7: 45961 | N7: 45991 | O7: 46022 | P7: 46053 | Q7: 46081 | R7: 46112 | S7: 46142 | T7: 46173 | U7: 46203 | W7: 45961 | X7: 45991 | Y7: 46022 | Z7: 46053 | AA7: 46081 | AB7: 46112 | AC7: 46142 | AD7: 46173 | AE7: 46203 | AG7: 45961 | AH7: 45991 | AI7: 46022 | AJ7: 46053 | AK7: 46081 | AL7: 46112 | AM7: 46142 | AN7: 46173 | AO7: 46203 | AQ7: 45961 | AR7: 45991 | AS7: 46022 | AT7: 46053 | AU7: 46081 | AV7: 46112 | AW7: 46142 | AX7: 46173 | AY7: 46203
C8: N | D8: Prénom | E8: Nom | F8: Classe | G8: Date de naisssance | H8: =+SUM(H9:H41) -> 0 | I8: =+SUM(I9:I41) -> 0 | J8: =+SUM(J9:J41) -> 0 | K8: =+SUM(K9:K41) -> 0 | L8: =+SUM(L9:L41) -> 0 | M8: =+SUM(M9:M29) -> 0 | N8: =+SUM(N9:N29) -> 0 | O8: =+SUM(O9:O29) -> 0 | P8: =+SUM(P9:P29) -> 0 | Q8: =+SUM(Q9:Q29) -> 0 | R8: =+SUM(R9:R29) -> 0 | S8: =+SUM(S9:S29) -> 0 | T8: =+SUM(T9:T29) -> 0 | U8: =+SUM(U9:U29) -> 0 | W8: =+SUM(W9:W29) -> 0 | X8: =+SUM(X9:X29) -> 0 | Y8: =+SUM(Y9:Y29) -> 0 | Z8: =+SUM(Z9:Z29) -> 0 | AA8: =+SUM(AA9:AA29) -> 0 | AB8: =+SUM(AB9:AB29) -> 0 | AC8: =+SUM(AC9:AC29) -> 0 | AD8: =+SUM(AD9:AD29) -> 0 | AE8: =+SUM(AE9:AE29) -> 0 | AG8: =+SUM(AG9:AG29) -> 0 | AH8: =+SUM(AH9:AH29) -> 0 | AI8: =+SUM(AI9:AI29) -> 0 | AJ8: =+SUM(AJ9:AJ29) -> 0 | AK8: =+SUM(AK9:AK29) -> 0 | AL8: =+SUM(AL9:AL29) -> 0 | AM8: =+SUM(AM9:AM29) -> 0 | AN8: =+SUM(AN9:AN29) -> 0 | AO8: =+SUM(AO9:AO29) -> 0 | AQ8: =+SUM(AQ9:AQ29) -> 0 | AR8: =+SUM(AR9:AR29) -> 0 | AS8: =+SUM(AS9:AS29) -> 0 | AT8: =+SUM(AT9:AT29) -> 0 | AU8: =+SUM(AU9:AU29) -> 0 | AV8: =+SUM(AV9:AV29) -> 0 | AW8: =+SUM(AW9:AW29) -> 0 | AX8: =+SUM(AX9:AX29) -> 0 | AY8: =+SUM(AY9:AY29) -> 0
C9: 1
C10: =+C9+1 -> 2
C11: =+C10+1 -> 3
C12: =+C11+1 -> 4
C13: =+C12+1 -> 5
C14: =+C13+1 -> 6
C15: =+C14+1 -> 7
C16: =+C15+1 -> 8
C17: =+C16+1 -> 9
C18: =+C17+1 -> 10
C19: =+C18+1 -> 11
C20: =+C19+1 -> 12
C21: =+C20+1 -> 13
... C28: =+C27+1 -> 20

Sheet ENCAIS
E3: MONTANT CHIFFRES D'AFFAIRES | Q3: TOTAL
C4: INTITULE | D4: EFFECTIF | E4: 45961 | F4: 45991 | G4: 46022 | H4: 46053 | I4: 46081 | J4: 46112 | K4: 46142 | L4: 46173 | M4: 46203 | N4: 46234 | O4: 46265 | P4: 46295
C5: Inscription totale reçue Garderie | D5: =+COUNTA(GARDERIE!H9:H48) -> 0 | E5: =+GARDERIE!I8 -> 0 | Q5: =+SUM(E5:P5) -> 0 | R5: =+Q5+Q17 -> 0 | S5: Garderie
C6: Inscription totale reçue de PS | D6: =+COUNTA(PS!H9:H48) -> 0 | E6: =+PS!I8 -> 0 | Q6: =+SUM(E6:P6) -> 0 | R6: =+Q6+Q18 -> 0 | S6: PS
C7: Inscription totale reçue de MS | D7: =+COUNTA(MS!H9:H48) -> 0 | E7: =+MS!I8 -> 0 | Q7: =+SUM(E7:P7) -> 0 | R7: =+Q7+Q19 -> 0 | S7: MS
C8: Inscription totale reçue de GS | D8: =+COUNTA(GS!H9:H48) -> 0 | E8: =+GS!I8 -> 0 | Q8: =+SUM(E8:P8) -> 0 | R8: =+Q8+Q20 -> 0 | S8: GS
C9: Inscription totale reçue de CI | D9: =+COUNTA(CI!H9:H48) -> 0 | E9: =+CI!I8 -> 0 | Q9: =+SUM(E9:P9) -> 0 | R9: =+Q9+Q21 -> 0 | S9: CI
C10: Inscription totale reçue de CP | D10: =+COUNTA(CP!H9:H48) -> 0 | E10: =+CP!I8 -> 0 | Q10: =+SUM(E10:P10) -> 0 | R10: =+Q10+Q22 -> 0 | S10: CP
C11: Inscription totale reçue de CE1 | D11: =+COUNTA('CE1'!H9:H48) -> 0 | E11: =+'CE1'!I8 -> 0 | Q11: =+SUM(E11:P11) -> 0 | R11: =+Q11+Q23 -> 0 | S11: CE1
C12: Inscription totale reçue de CE2 | D12: =+COUNTA('CE2'!H9:H48) -> 0 | E12: =+'CE2'!I8 -> 0 | Q12: =+SUM(E12:P12) -> 0 | R12: =+Q12+Q24 -> 0 | S12: CE2
C13: Inscription totale reçue de CM1 | D13: =+COUNTA('CM1'!H9:H48) -> 0 | E13: =+'CM1'!I8 -> 0 | Q13: =+SUM(E13:P13) -> 0 | R13: =+Q13+Q25 -> 0 | S13: CM1
C14: Inscription totale reçue de CM2 | D14: =+COUNTA('CM2'!H9:H48) -> 0 | E14: =+'CM2'!I8 -> 0 | Q14: =+SUM(E14:P14) -> 0 | R14: =+Q14+Q26 -> 0 | S14: CM2
C16: Total inscription reçue | D16: =+SUM(D5:D15) -> 0 | E16: =+SUM(E5:E15) -> 0 | F16: =+SUM(F5:F15) -> 0 | G16: =+SUM(G5:G15) -> 0 | H16: =+SUM(H5:H15) -> 0 | I16: =+SUM(I5:I15) -> 0 | J16: =+SUM(J5:J15) -> 0 | K16: =+SUM(K5:K15) -> 0 | ... Q16: =+SUM(Q5:Q15) -> 0
C17: Mensualité totale reçue Garderie | D17: =D5 -> 0 | E17: =+GARDERIE!M8 -> 0 | F17: =+GARDERIE!N8 -> 0 | G17: =+GARDERIE!O8 -> 0 | H17: =+GARDERIE!P8 -> 0 | I17: =+GARDERIE!Q8 -> 0 | J17: =+GARDERIE!R8 -> 0 | K17: =+GARDERIE!S8 -> 0 | L17: =+GARDERIE!T8 -> 0 | M17: =+GARDERIE!U8 -> 0 | Q17: =+SUM(E17:P17) -> 0
C18: Mensualité totale reçue de PS | D18: =D6 -> 0 | E18: =+PS!M8 -> 0 | F18: =+PS!N8 -> 0 | G18: =+PS!O8 -> 0 | H18: =+PS!P8 -> 0 | I18: =+PS!Q8 -> 0 | J18: =+PS!R8 -> 0 | K18: =+PS!S8 -> 0 | L18: =+PS!T8 -> 0 | M18: =+PS!U8 -> 0 | Q18: =+SUM(E18:P18) -> 0
C19: Mensualité totale reçue de MS | D19: =D7 -> 0 | E19: =+MS!M8 -> 0 | F19: =+MS!N8 -> 0 | G19: =+MS!O8 -> 0 | H19: =+MS!P8 -> 0 | I19: =+MS!Q8 -> 0 | J19: =+MS!R8 -> 0 | K19: =+MS!S8 -> 0 | L19: =+MS!T8 -> 0 | M19: =+MS!U8 -> 0 | Q19: =+SUM(E19:P19) -> 0
C20: Mensualité totale reçue de GS | D20: =D8 -> 0 | E20: =+GS!M8 -> 0 | F20: =+GS!N8 -> 0 | G20: =+GS!O8 -> 0 | H20: =+GS!P8 -> 0 | I20: =+GS!Q8 -> 0 | J20: =+GS!R8 -> 0 | K20: =+GS!S8 -> 0 | L20: =+GS!T8 -> 0 | M20: =+GS!U8 -> 0 | Q20: =+SUM(E20:P20) -> 0
C21: Mensualité totale reçue de CI | D21: =D9 -> 0 | E21: =+CI!M8 -> 0 | F21: =+CP!N8 -> 0 | G21: =+CP!O8 -> 0 | H21: =+CP!P8 -> 0 | I21: =+CP!Q8 -> 0 | J21: =+CP!R8 -> 0 | K21: =+CP!S8 -> 0 | L21: =+CP!T8 -> 0 | M21: =+CP!U8 -> 0 | Q21: =+SUM(E21:P21) -> 0
C22: Mensualité totale reçue de CP | D22: =D10 -> 0 | E22: =+CP!M8 -> 0 | F22: =+CP!N8 -> 0 | G22: =+CP!O8 -> 0 | H22: =+CP!P8 -> 0 | I22: =+CP!Q8 -> 0 | J22: =+CP!R8 -> 0 | K22: =+CP!S8 -> 0 | L22: =+CP!T8 -> 0 | M22: =+CP!U8 -> 0 | Q22: =+SUM(E22:P22) -> 0
C23: Mensualité totale reçue de CE1 | D23: =D11 -> 0 | E23: =+'CE1'!M8 -> 0 | F23: =+'CE1'!N8 -> 0 | G23: =+'CE1'!O8 -> 0 | H23: =+'CE1'!P8 -> 0 | I23: =+'CE1'!Q8 -> 0 | J23: =+'CE1'!R8 -> 0 | K23: =+'CE1'!S8 -> 0 | L23: =+'CE1'!T8 -> 0 | M23: =+'CE1'!U8 -> 0 | Q23: =+SUM(E23:P23) -> 0
C24: Mensualité totale reçue de CE2 | D24: =D12 -> 0 | E24: =+'CE2'!M8 -> 0 | F24: =+'CE2'!N8 -> 0 | G24: =+'CE2'!O8 -> 0 | H24: =+'CE2'!P8 -> 0 | I24: =+'CE2'!Q8 -> 0 | J24: =+'CE2'!R8 -> 0 | K24: =+'CE2'!S8 -> 0 | L24: =+'CE2'!T8 -> 0 | M24: =+'CE2'!U8 -> 0 | Q24: =+SUM(E24:P24) -> 0
C25: Mensualité totale reçue de CM1 | D25: =D13 -> 0 | E25: =+'CM1'!M8 -> 0 | F25: =+'CM1'!N8 -> 0 | G25: =+'CM1'!O8 -> 0 | H25: =+'CM1'!P8 -> 0 | I25: =+'CM1'!Q8 -> 0 | J25: =+'CM1'!R8 -> 0 | K25: =+'CM1'!S8 -> 0 | L25: =+'CM1'!T8 -> 0 | M25: =+'CM1'!U8 -> 0 | Q25: =+SUM(E25:P25) -> 0
C26: Mensualité totale reçue de CM2 | D26: =D14 -> 0 | E26: =+'CM2'!M8 -> 0 | F26: =+'CM2'!N8 -> 0 | G26: =+'CM2'!O8 -> 0 | H26: =+'CM2'!P8 -> 0 | I26: =+'CM2'!Q8 -> 0 | J26: =+'CM2'!R8 -> 0 | K26: =+'CM2'!S8 -> 0 | L26: =+'CM2'!T8 -> 0 | M26: =+'CM2'!U8 -> 0 | Q26: =+SUM(E26:P26) -> 0
C28: Total mensualité reçue | D28: =+SUM(D17:D26) -> 0 | E28: =+SUM(E17:E27) -> 0 | F28: =+SUM(F17:F27) -> 0 | G28: =+SUM(G17:G27) -> 0 | H28: =+SUM(H17:H27) -> 0 | I28: =+SUM(I17:I27) -> 0 | J28: =+SUM(J17:J27) -> 0 | K28: =+SUM(K17:K27) -> 0 | L28: =+SUM(L17:L27) -> 0 | M28: =+SUM(M17:M27) -> 0 | Q28: =+SUM(Q17:Q27) -> 0
C30: TOTAL | E30: =+E16+E28 -> 0 | F30: =+F16+F28 -> 0 | G30: =+G16+G28 -> 0 | H30: =+H16+H28 -> 0 | I30: =+I16+I28 -> 0 | J30: =+J16+J28 -> 0 | K30: =+K16+K28 -> 0 | L30: =+L16+L28 -> 0 | ... Q30: =+Q16+Q28 -> 0
C33: TOTAL GENERAL | E33: =+E16+E30 -> 0 | F33: =+F16+F30 -> 0 | G33: =+G16+G30 -> 0 | H33: =+H16+H30 -> 0 | I33: =+I16+I30 -> 0 | J33: =+J16+J30 -> 0 | K33: =+K16+K30 -> 0 | L33: =+L16+L30 -> 0 | ... P33: =+P16+P30 -> 0 | Q33: =Q30+Q16 -> 0
E36: MONTANT CANTINE | Q36: TOTAL
C37: INTITULE | E37: =+E4 -> 45961 | F37: =+F4 -> 45991 | G37: =+G4 -> 46022 | H37: =+H4 -> 46053 | I37: =+I4 -> 46081 | J37: =+J4 -> 46112 | K37: =+K4 -> 46142 | L37: =+L4 -> 46173 | ... P37: =+P4 -> 46295
C38: Cantine Garderie | E38: =+GARDERIE!W8 -> 0 | F38: =+GARDERIE!X8 -> 0 | G38: =+GARDERIE!Y8 -> 0 | H38: =+GARDERIE!Z8 -> 0 | I38: =+GARDERIE!AA8 -> 0 | J38: =+GARDERIE!AB8 -> 0 | K38: =+GARDERIE!AC8 -> 0 | L38: =+GARDERIE!AD8 -> 0 | M38: =+GARDERIE!AE8 -> 0 | Q38: =+SUM(E38:M38) -> 0
C39: Cantine de PS | E39: =PS!W8 -> 0 | F39: =PS!X8 -> 0 | G39: =PS!Y8 -> 0 | H39: =PS!Z8 -> 0 | I39: =PS!AA8 -> 0 | J39: =PS!AB8 -> 0 | K39: =PS!AC8 -> 0 | L39: =PS!AD8 -> 0 | M39: =PS!AE8 -> 0 | Q39: =+SUM(E39:M39) -> 0
C40: Cantine de MS | E40: =MS!W8 -> 0 | F40: =MS!X8 -> 0 | G40: =MS!Y8 -> 0 | H40: =MS!Z8 -> 0 | I40: =MS!AA8 -> 0 | J40: =MS!AB8 -> 0 | K40: =MS!AC8 -> 0 | L40: =MS!AD8 -> 0 | M40: =MS!AE8 -> 0 | Q40: =+SUM(E40:M40) -> 0
C41: Cantine de GS | E41: =GS!W8 -> 0 | F41: =GS!X8 -> 0 | G41: =GS!Y8 -> 0 | H41: =GS!Z8 -> 0 | I41: =GS!AA8 -> 0 | J41: =GS!AB8 -> 0 | K41: =GS!AC8 -> 0 | L41: =GS!AD8 -> 0 | M41: =GS!AE8 -> 0 | Q41: =+SUM(E41:M41) -> 0
C42: Cantine de CI | E42: =+CI!W8 -> 0 | F42: =+CI!X8 -> 0 | G42: =+CI!Y8 -> 0 | H42: =+CI!Z8 -> 0 | I42: =+CI!AA8 -> 0 | J42: =+CI!AB8 -> 0 | K42: =+CI!AC8 -> 0 | L42: =+CI!AD8 -> 0 | M42: =+CI!AE8 -> 0 | Q42: =+SUM(E42:M42) -> 0
C43: Cantine de CP | E43: =+CP!W8 -> 0 | F43: =+CP!X8 -> 0 | G43: =+CP!Y8 -> 0 | H43: =+CP!Z8 -> 0 | I43: =+CP!AA8 -> 0 | J43: =+CP!AB8 -> 0 | K43: =+CP!AC8 -> 0 | L43: =+CP!AD8 -> 0 | M43: =+CP!AE8 -> 0 | Q43: =+SUM(E43:M43) -> 0
C44: Cantine de CE1 | E44: =+'CE1'!W8 -> 0 | F44: =+'CE1'!X8 -> 0 | G44: =+'CE1'!Y8 -> 0 | H44: =+'CE1'!Z8 -> 0 | I44: =+'CE1'!AA8 -> 0 | J44: =+'CE1'!AB8 -> 0 | K44: =+'CE1'!AC8 -> 0 | L44: =+'CE1'!AD8 -> 0 | M44: =+'CE1'!AE8 -> 0 | Q44: =+SUM(E44:M44) -> 0
C45: Cantine de CE2 | E45: =+'CE2'!W8 -> 0 | F45: =+'CE2'!X8 -> 0 | G45: =+'CE2'!Y8 -> 0 | H45: =+'CE2'!Z8 -> 0 | I45: =+'CE2'!AA8 -> 0 | J45: =+'CE2'!AB8 -> 0 | K45: =+'CE2'!AC8 -> 0 | L45: =+'CE2'!AD8 -> 0 | M45: =+'CE2'!AE8 -> 0 | Q45: =+SUM(E45:M45) -> 0
C46: Cantine de CM1 | E46: =+'CM1'!W8 -> 0 | F46: =+'CM1'!X8 -> 0 | G46: =+'CM1'!Y8 -> 0 | H46: =+'CM1'!Z8 -> 0 | I46: =+'CM1'!AA8 -> 0 | J46: =+'CM1'!AB8 -> 0 | K46: =+'CM1'!AC8 -> 0 | L46: =+'CM1'!AD8 -> 0 | M46: =+'CM1'!AE8 -> 0 | Q46: =+SUM(E46:M46) -> 0
C47: Cantine de CM2 | E47: =+'CM2'!W8 -> 0 | F47: =+'CM2'!X8 -> 0 | G47: =+'CM2'!Y8 -> 0 | H47: =+'CM2'!Z8 -> 0 | I47: =+'CM2'!AA8 -> 0 | J47: =+'CM2'!AB8 -> 0 | K47: =+'CM2'!AC8 -> 0 | L47: =+'CM2'!AD8 -> 0 | M47: =+'CM2'!AE8 -> 0 | Q47: =+SUM(E47:M47) -> 0
C49: Total reçu | D49: =+SUM(D38:D47) -> 0 | E49: =+SUM(E38:E47) -> 0 | F49: =+SUM(F38:F47) -> 0 | G49: =+SUM(G38:G47) -> 0 | H49: =+SUM(H38:H47) -> 0 | I49: =+SUM(I38:I47) -> 0 | J49: =+SUM(J38:J47) -> 0 | K49: =+SUM(K38:K47) -> 0 | ... M49: =+SUM(M38:M47) -> 0 | Q49: =+SUM(Q38:Q47) -> 0
C50: Paiement cantine | Q50: =+SUM(E50:M50) -> 0
...

Sheet Rapport Bilan
E3: RAPPORT BILAN ANNEE SCOLAIRE 2025/2026
E4: ="AU "&TEXT(TODAY(),"jj/mm/aaaa") -> AU 14/10/2025
E8: 45961 | F8: 45991 | G8: 46022 | H8: 46053 | I8: 46081 | J8: 46112 | K8: 46142 | L8: 46173 | M8: 46203 | N8: 46234 | O8: 46265 | P8: 46295
C9: RUBRIQUE | E9: 45961 | F9: 45991 | G9: 46022 | H9: 46053 | I9: 46081 | J9: 46112 | K9: 46142 | L9: 46173 | M9: 46203 | N9: 46234 | O9: 46265 | P9: 46295 | Q9: TOTAL 2425 | R9: POIDS
R11: =+IFERROR(Q11/$Q$16,"")
C12: TOTAL INSCRIPTION REÇUE | E12: =+ENCAIS!E16 -> 0 | F12: =+ENCAIS!F16 -> 0 | G12: =+ENCAIS!G16 -> 0 | H12: =+ENCAIS!H16 -> 0 | I12: =+ENCAIS!I16 -> 0 | J12: =+ENCAIS!J16 -> 0 | K12: =+ENCAIS!K16 -> 0 | L12: =+ENCAIS!L16 -> 0 | ... P12: =+ENCAIS!P16 -> 0 | Q12: =+SUM(E12:O12) -> 0 | R12: =+IFERROR(Q12/$Q$16,"")
C13: TOTAL MENSUALITÉ REÇUE | E13: =+ENCAIS!E28 -> 0 | F13: =+ENCAIS!F28 -> 0 | G13: =+ENCAIS!G28 -> 0 | H13: =+ENCAIS!H28 -> 0 | I13: =+ENCAIS!I28 -> 0 | J13: =+ENCAIS!J28 -> 0 | K13: =+ENCAIS!K28 -> 0 | L13: =+ENCAIS!L28 -> 0 | ... P13: =+ENCAIS!P28 -> 0 | Q13: =+SUM(E13:O13) -> 0 | R13: =+IFERROR(Q13/$Q$16,"")
C14: AUTRE PRODUIT | R14: =+IFERROR(Q14/$Q$16,"")
C16: TOTAL RESSOURCE | E16: =+SUM(E11:E15) -> 0 | F16: =+SUM(F11:F15) -> 0 | G16: =+SUM(G11:G15) -> 0 | H16: =+SUM(H11:H15) -> 0 | I16: =+SUM(I11:I15) -> 0 | J16: =+SUM(J11:J15) -> 0 | K16: =+SUM(K11:K15) -> 0 | L16: =+SUM(L11:L15) -> 0 | ... Q16: =+SUM(Q11:Q15) -> 0 | R16: =+SUM(R11:R13) -> 0
C18: ARRIERE SALAIRE PAYE | E18: =+SUMIFS(DEPENSES!$H:$H,DEPENSES!$J:$J,'Rapport Bilan'!$C18,DEPENSES!$B:$B,'Rapport Bilan'!E$8) -> 0 | F18: =+SUMIFS(DEPENSES!$H:$H,DEPENSES!$J:$J,'Rapport Bilan'!$C18,DEPENSES!$B:$B,'Rapport Bilan'!F$8) -> 0 | G18: =+SUMIFS(DEPENSES!$H:$H,DEPENSES!$J:$J,'Rapport Bilan'!$C18,DEPENSES!$B:$B,'Rapport Bilan'!G$8) -> 0 | H18: =+SUMIFS(DEPENSES!$H:$H,DEPENSES!$J:$J,'Rapport Bilan'!$C18,DEPENSES!$B:$B,'Rapport Bilan'!H$8) -> 0 | I18: =+SUMIFS(DEPENSES!$H:$H,DEPENSES!$J:$J,'Rapport Bilan'!$C18,DEPENSES!$B:$B,'Rapport Bilan'!I$8) -> 0 | J18: =+SUMIFS(DEPENSES!$H:$H,DEPENSES!$J:$J,'Rapport Bilan'!$C18,DEPENSES!$B:$B,'Rapport Bilan'!J$8) -> 0 | K18: =+SUMIFS(DEPENSES!$H:$H,DEPENSES!$J:$J,'Rapport Bilan'!$C18,DEPENSES!$B:$B,'Rapport Bilan'!K$8) -> 0 | L18: =+SUMIFS(DEPENSES!$H:$H,DEPENSES!$J:$J,'Rapport Bilan'!$C18,DEPENSES!$B:$B,'Rapport Bilan'!L$8) -> 0 | ... P18: =+SUMIFS(DEPENSES!$H:$H,DEPENSES!$J:$J,'Rapport Bilan'!$C18,DEPENSES!$B:$B,'Rapport Bilan'!P$8) -> 0 | Q18: =+SUM(E18:O18) -> 0 | R18: =+IFERROR(Q18/$Q$35,"")
C19: LOCATIONS DE BÂTIMENTS | E19: =+SUMIFS(DEPENSES!$H:$H,DEPENSES!$J:$J,'Rapport Bilan'!$C19,DEPENSES!$B:$B,'Rapport Bilan'!E$8) -> 0 | F19: =+SUMIFS(DEPENSES!$H:$H,DEPENSES!$J:$J,'Rapport Bilan'!$C19,DEPENSES!$B:$B,'Rapport Bilan'!F$8) -> 0 | G19: =+SUMIFS(DEPENSES!$H:$H,DEPENSES!$J:$J,'Rapport Bilan'!$C19,DEPENSES!$B:$B,'Rapport Bilan'!G$8) -> 0 | H19: =+SUMIFS(DEPENSES!$H:$H,DEPENSES!$J:$J,'Rapport Bilan'!$C19,DEPENSES!$B:$B,'Rapport Bilan'!H$8) -> 0 | I19: =+SUMIFS(DEPENSES!$H:$H,DEPENSES!$J:$J,'Rapport Bilan'!$C19,DEPENSES!$B:$B,'Rapport Bilan'!I$8) -> 0 | J19: =+SUMIFS(DEPENSES!$H:$H,DEPENSES!$J:$J,'Rapport Bilan'!$C19,DEPENSES!$B:$B,'Rapport Bilan'!J$8) -> 0 | K19: =+SUMIFS(DEPENSES!$H:$H,DEPENSES!$J:$J,'Rapport Bilan'!$C19,DEPENSES!$B:$B,'Rapport Bilan'!K$8) -> 0 | L19: =+SUMIFS(DEPENSES!$H:$H,DEPENSES!$J:$J,'Rapport Bilan'!$C19,DEPENSES!$B:$B,'Rapport Bilan'!L$8) -> 0 | ... P19: =+SUMIFS(DEPENSES!$H:$H,DEPENSES!$J:$J,'Rapport Bilan'!$C19,DEPENSES!$B:$B,'Rapport Bilan'!P$8) -> 0 | Q19: =+SUM(E19:O19) -> 0 | R19: =+IFERROR(Q19/$Q$35,"")
C20: SALAIRE | E20: =+SUMIFS(DEPENSES!$H:$H,DEPENSES!$J:$J,'Rapport Bilan'!$C20,DEPENSES!$B:$B,'Rapport Bilan'!E$8) -> 0 | F20: =+SUMIFS(DEPENSES!$H:$H,DEPENSES!$J:$J,'Rapport Bilan'!$C20,DEPENSES!$B:$B,'Rapport Bilan'!F$8) -> 0 | G20: =+SUMIFS(DEPENSES!$H:$H,DEPENSES!$J:$J,'Rapport Bilan'!$C20,DEPENSES!$B:$B,'Rapport Bilan'!G$8) -> 0 | H20: =+SUMIFS(DEPENSES!$H:$H,DEPENSES!$J:$J,'Rapport Bilan'!$C20,DEPENSES!$B:$B,'Rapport Bilan'!H$8) -> 0 | I20: =+SUMIFS(DEPENSES!$H:$H,DEPENSES!$J:$J,'Rapport Bilan'!$C20,DEPENSES!$B:$B,'Rapport Bilan'!I$8) -> 0 | J20: =+SUMIFS(DEPENSES!$H:$H,DEPENSES!$J:$J,'Rapport Bilan'!$C20,DEPENSES!$B:$B,'Rapport Bilan'!J$8) -> 0 | K20: =+SUMIFS(DEPENSES!$H:$H,DEPENSES!$J:$J,'Rapport Bilan'!$C20,DEPENSES!$B:$B,'Rapport Bilan'!K$8) -> 0 | L20: =+SUMIFS(DEPENSES!$H:$H,DEPENSES!$J:$J,'Rapport Bilan'!$C20,DEPENSES!$B:$B,'Rapport Bilan'!L$8) -> 0 | ... P20: =+SUMIFS(DEPENSES!$H:$H,DEPENSES!$J:$J,'Rapport Bilan'!$C20,DEPENSES!$B:$B,'Rapport Bilan'!P$8) -> 0 | Q20: =+SUM(E20:O20) -> 0 | R20: =+IFERROR(Q20/$Q$35,"")
C21: EAU EXPLOITATION - SEN'EAU | E21: =+SUMIFS(DEPENSES!$H:$H,DEPENSES!$J:$J,'Rapport Bilan'!$C21,DEPENSES!$B:$B,'Rapport Bilan'!E$8) -> 0 | F21: =+SUMIFS(DEPENSES!$H:$H,DEPENSES!$J:$J,'Rapport Bilan'!$C21,DEPENSES!$B:$B,'Rapport Bilan'!F$8) -> 0 | G21: =+SUMIFS(DEPENSES!$H:$H,DEPENSES!$J:$J,'Rapport Bilan'!$C21,DEPENSES!$B:$B,'Rapport Bilan'!G$8) -> 0 | H21: =+SUMIFS(DEPENSES!$H:$H,DEPENSES!$J:$J,'Rapport Bilan'!$C21,DEPENSES!$B:$B,'Rapport Bilan'!H$8) -> 0 | I21: =+SUMIFS(DEPENSES!$H:$H,DEPENSES!$J:$J,'Rapport Bilan'!$C21,DEPENSES!$B:$B,'Rapport Bilan'!I$8) -> 0 | J21: =+SUMIFS(DEPENSES!$H:$H,DEPENSES!$J:$J,'Rapport Bilan'!$C21,DEPENSES!$B:$B,'Rapport Bilan'!J$8) -> 0 | K21: =+SUMIFS(DEPENSES!$H:$H,DEPENSES!$J:$J,'Rapport Bilan'!$C21,DEPENSES!$B:$B,'Rapport Bilan'!K$8) -> 0 | L21: =+SUMIFS(DEPENSES!$H:$H,DEPENSES!$J:$J,'Rapport Bilan'!$C21,DEPENSES!$B:$B,'Rapport Bilan'!L$8) -> 0 | ... P21: =+SUMIFS(DEPENSES!$H:$H,DEPENSES!$J:$J,'Rapport Bilan'!$C21,DEPENSES!$B:$B,'Rapport Bilan'!P$8) -> 0 | Q21: =+SUM(E21:O21) -> 0 | R21: =+IFERROR(Q21/$Q$35,"")
C22: ELECTRICITÉ EXPLOITATION - SENELEC | E22: =+SUMIFS(DEPENSES!$H:$H,DEPENSES!$J:$J,'Rapport Bilan'!$C22,DEPENSES!$B:$B,'Rapport Bilan'!E$8) -> 0 | F22: =+SUMIFS(DEPENSES!$H:$H,DEPENSES!$J:$J,'Rapport Bilan'!$C22,DEPENSES!$B:$B,'Rapport Bilan'!F$8) -> 0 | G22: =+SUMIFS(DEPENSES!$H:$H,DEPENSES!$J:$J,'Rapport Bilan'!$C22,DEPENSES!$B:$B,'Rapport Bilan'!G$8) -> 0 | H22: =+SUMIFS(DEPENSES!$H:$H,DEPENSES!$J:$J,'Rapport Bilan'!$C22,DEPENSES!$B:$B,'Rapport Bilan'!H$8) -> 0 | I22: =+SUMIFS(DEPENSES!$H:$H,DEPENSES!$J:$J,'Rapport Bilan'!$C22,DEPENSES!$B:$B,'Rapport Bilan'!I$8) -> 0 | J22: =+SUMIFS(DEPENSES!$H:$H,DEPENSES!$J:$J,'Rapport Bilan'!$C22,DEPENSES!$B:$B,'Rapport Bilan'!J$8) -> 0 | K22: =+SUMIFS(DEPENSES!$H:$H,DEPENSES!$J:$J,'Rapport Bilan'!$C22,DEPENSES!$B:$B,'Rapport Bilan'!K$8) -> 0 | L22: =+SUMIFS(DEPENSES!$H:$H,DEPENSES!$J:$J,'Rapport Bilan'!$C22,DEPENSES!$B:$B,'Rapport Bilan'!L$8) -> 0 | ... P22: =+SUMIFS(DEPENSES!$H:$H,DEPENSES!$J:$J,'Rapport Bilan'!$C22,DEPENSES!$B:$B,'Rapport Bilan'!P$8) -> 0 | Q22: =+SUM(E22:O22) -> 0 | R22: =+IFERROR(Q22/$Q$35,"")
C23: FOURNITURES D'ENTRETIEN , DE BUREAU ET SCOLAIRE | E23: =+SUMIFS(DEPENSES!$H:$H,DEPENSES!$J:$J,'Rapport Bilan'!$C23,DEPENSES!$B:$B,'Rapport Bilan'!E$8) -> 0 | F23: =+SUMIFS(DEPENSES!$H:$H,DEPENSES!$J:$J,'Rapport Bilan'!$C23,DEPENSES!$B:$B,'Rapport Bilan'!F$8) -> 0 | G23: =+SUMIFS(DEPENSES!$H:$H,DEPENSES!$J:$J,'Rapport Bilan'!$C23,DEPENSES!$B:$B,'Rapport Bilan'!G$8) -> 0 | H23: =+SUMIFS(DEPENSES!$H:$H,DEPENSES!$J:$J,'Rapport Bilan'!$C23,DEPENSES!$B:$B,'Rapport Bilan'!H$8) -> 0 | I23: =+SUMIFS(DEPENSES!$H:$H,DEPENSES!$J:$J,'Rapport Bilan'!$C23,DEPENSES!$B:$B,'Rapport Bilan'!I$8) -> 0 | J23: =+SUMIFS(DEPENSES!$H:$H,DEPENSES!$J:$J,'Rapport Bilan'!$C23,DEPENSES!$B:$B,'Rapport Bilan'!J$8) -> 0 | K23: =+SUMIFS(DEPENSES!$H:$H,DEPENSES!$J:$J,'Rapport Bilan'!$C23,DEPENSES!$B:$B,'Rapport Bilan'!K$8) -> 0 | L23: =+SUMIFS(DEPENSES!$H:$H,DEPENSES!$J:$J,'Rapport Bilan'!$C23,DEPENSES!$B:$B,'Rapport Bilan'!L$8) -> 0 | ... P23: =+SUMIFS(DEPENSES!$H:$H,DEPENSES!$J:$J,'Rapport Bilan'!$C23,DEPENSES!$B:$B,'Rapport Bilan'!P$8) -> 0 | Q23: =+SUM(E23:O23) -> 0 | R23: =+IFERROR(Q23/$Q$35,"")
C24: AUTRE PETIT MATÉRIEL | E24: =+SUMIFS(DEPENSES!$H:$H,DEPENSES!$J:$J,'Rapport Bilan'!$C24,DEPENSES!$B:$B,'Rapport Bilan'!E$8) -> 0 | F24: =+SUMIFS(DEPENSES!$H:$H,DEPENSES!$J:$J,'Rapport Bilan'!$C24,DEPENSES!$B:$B,'Rapport Bilan'!F$8) -> 0 | G24: =+SUMIFS(DEPENSES!$H:$H,DEPENSES!$J:$J,'Rapport Bilan'!$C24,DEPENSES!$B:$B,'Rapport Bilan'!G$8) -> 0 | H24: =+SUMIFS(DEPENSES!$H:$H,DEPENSES!$J:$J,'Rapport Bilan'!$C24,DEPENSES!$B:$B,'Rapport Bilan'!H$8) -> 0 | I24: =+SUMIFS(DEPENSES!$H:$H,DEPENSES!$J:$J,'Rapport Bilan'!$C24,DEPENSES!$B:$B,'Rapport Bilan'!I$8) -> 0 | J24: =+SUMIFS(DEPENSES!$H:$H,DEPENSES!$J:$J,'Rapport Bilan'!$C24,DEPENSES!$B:$B,'Rapport Bilan'!J$8) -> 0 | K24: =+SUMIFS(DEPENSES!$H:$H,DEPENSES!$J:$J,'Rapport Bilan'!$C24,DEPENSES!$B:$B,'Rapport Bilan'!K$8) -> 0 | L24: =+SUMIFS(DEPENSES!$H:$H,DEPENSES!$J:$J,'Rapport Bilan'!$C24,DEPENSES!$B:$B,'Rapport Bilan'!L$8) -> 0 | ... P24: =+SUMIFS(DEPENSES!$H:$H,DEPENSES!$J:$J,'Rapport Bilan'!$C24,DEPENSES!$B:$B,'Rapport Bilan'!P$8) -> 0 | Q24: =+SUM(E24:O24) -> 0 | R24: =+IFERROR(Q24/$Q$35,"")
C25: MATÉRIELS ET ÉQUIPEMENTS PEDAGOGIQUE | E25: =+SUMIFS(DEPENSES!$H:$H,DEPENSES!$J:$J,'Rapport Bilan'!$C25,DEPENSES!$B:$B,'Rapport Bilan'!E$8) -> 0 | F25: =+SUMIFS(DEPENSES!$H:$H,DEPENSES!$J:$J,'Rapport Bilan'!$C25,DEPENSES!$B:$B,'Rapport Bilan'!F$8) -> 0 | G25: =+SUMIFS(DEPENSES!$H:$H,DEPENSES!$J:$J,'Rapport Bilan'!$C25,DEPENSES!$B:$B,'Rapport Bilan'!G$8) -> 0 | H25: =+SUMIFS(DEPENSES!$H:$H,DEPENSES!$J:$J,'Rapport Bilan'!$C25,DEPENSES!$B:$B,'Rapport Bilan'!H$8) -> 0 | I25: =+SUMIFS(DEPENSES!$H:$H,DEPENSES!$J:$J,'Rapport Bilan'!$C25,DEPENSES!$B:$B,'Rapport Bilan'!I$8) -> 0 | J25: =+SUMIFS(DEPENSES!$H:$H,DEPENSES!$J:$J,'Rapport Bilan'!$C25,DEPENSES!$B:$B,'Rapport Bilan'!J$8) -> 0 | K25: =+SUMIFS(DEPENSES!$H:$H,DEPENSES!$J:$J,'Rapport Bilan'!$C25,DEPENSES!$B:$B,'Rapport Bilan'!K$8) -> 0 | L25: =+SUMIFS(DEPENSES!$H:$H,DEPENSES!$J:$J,'Rapport Bilan'!$C25,DEPENSES!$B:$B,'Rapport Bilan'!L$8) -> 0 | ... P25: =+SUMIFS(DEPENSES!$H:$H,DEPENSES!$J:$J,'Rapport Bilan'!$C25,DEPENSES!$B:$B,'Rapport Bilan'!P$8) -> 0 | Q25: =+SUM(E25:O25) -> 0 | R25: =+IFERROR(Q25/$Q$35,"")
C26: TRAVAUX, ENTRETIEN ET RÉPARATIONS | E26: =+SUMIFS(DEPENSES!$H:$H,DEPENSES!$J:$J,'Rapport Bilan'!$C26,DEPENSES!$B:$B,'Rapport Bilan'!E$8) -> 0 | F26: =+SUMIFS(DEPENSES!$H:$H,DEPENSES!$J:$J,'Rapport Bilan'!$C26,DEPENSES!$B:$B,'Rapport Bilan'!F$8) -> 0 | G26: =+SUMIFS(DEPENSES!$H:$H,DEPENSES!$J:$J,'Rapport Bilan'!$C26,DEPENSES!$B:$B,'Rapport Bilan'!G$8) -> 0 | H26: =+SUMIFS(DEPENSES!$H:$H,DEPENSES!$J:$J,'Rapport Bilan'!$C26,DEPENSES!$B:$B,'Rapport Bilan'!H$8) -> 0 | I26: =+SUMIFS(DEPENSES!$H:$H,DEPENSES!$J:$J,'Rapport Bilan'!$C26,DEPENSES!$B:$B,'Rapport Bilan'!I$8) -> 0 | J26: =+SUMIFS(DEPENSES!$H:$H,DEPENSES!$J:$J,'Rapport Bilan'!$C26,DEPENSES!$B:$B,'Rapport Bilan'!J$8) -> 0 | K26: =+SUMIFS(DEPENSES!$H:$H,DEPENSES!$J:$J,'Rapport Bilan'!$C26,DEPENSES!$B:$B,'Rapport Bilan'!K$8) -> 0 | L26: =+SUMIFS(DEPENSES!$H:$H,DEPENSES!$J:$J,'Rapport Bilan'!$C26,DEPENSES!$B:$B,'Rapport Bilan'!L$8) -> 0 | ... P26: =+SUMIFS(DEPENSES!$H:$H,DEPENSES!$J:$J,'Rapport Bilan'!$C26,DEPENSES!$B:$B,'Rapport Bilan'!P$8) -> 0 | Q26: =+SUM(E26:O26) -> 0 | R26: =+IFERROR(Q26/$Q$35,"")
C27: TRANSPORTS FG | E27: =+SUMIFS(DEPENSES!$H:$H,DEPENSES!$J:$J,'Rapport Bilan'!$C27,DEPENSES!$B:$B,'Rapport Bilan'!E$8) -> 0 | F27: =+SUMIFS(DEPENSES!$H:$H,DEPENSES!$J:$J,'Rapport Bilan'!$C27,DEPENSES!$B:$B,'Rapport Bilan'!F$8) -> 0 | G27: =+SUMIFS(DEPENSES!$H:$H,DEPENSES!$J:$J,'Rapport Bilan'!$C27,DEPENSES!$B:$B,'Rapport Bilan'!G$8) -> 0 | H27: =+SUMIFS(DEPENSES!$H:$H,DEPENSES!$J:$J,'Rapport Bilan'!$C27,DEPENSES!$B:$B,'Rapport Bilan'!H$8) -> 0 | I27: =+SUMIFS(DEPENSES!$H:$H,DEPENSES!$J:$J,'Rapport Bilan'!$C27,DEPENSES!$B:$B,'Rapport Bilan'!I$8) -> 0 | J27: =+SUMIFS(DEPENSES!$H:$H,DEPENSES!$J:$J,'Rapport Bilan'!$C27,DEPENSES!$B:$B,'Rapport Bilan'!J$8) -> 0 | K27: =+SUMIFS(DEPENSES!$H:$H,DEPENSES!$J:$J,'Rapport Bilan'!$C27,DEPENSES!$B:$B,'Rapport Bilan'!K$8) -> 0 | L27: =+SUMIFS(DEPENSES!$H:$H,DEPENSES!$J:$J,'Rapport Bilan'!$C27,DEPENSES!$B:$B,'Rapport Bilan'!L$8) -> 0 | ... P27: =+SUMIFS(DEPENSES!$H:$H,DEPENSES!$J:$J,'Rapport Bilan'!$C27,DEPENSES!$B:$B,'Rapport Bilan'!P$8) -> 0 | Q27: =+SUM(E27:O27) -> 0 | R27: =+IFERROR(Q27/$Q$35,"")
C28: ASSURANCES | E28: =+SUMIFS(DEPENSES!$H:$H,DEPENSES!$J:$J,'Rapport Bilan'!$C28,DEPENSES!$B:$B,'Rapport Bilan'!E$8) -> 0 | F28: =+SUMIFS(DEPENSES!$H:$H,DEPENSES!$J:$J,'Rapport Bilan'!$C28,DEPENSES!$B:$B,'Rapport Bilan'!F$8) -> 0 | G28: =+SUMIFS(DEPENSES!$H:$H,DEPENSES!$J:$J,'Rapport Bilan'!$C28,DEPENSES!$B:$B,'Rapport Bilan'!G$8) -> 0 | H28: =+SUMIFS(DEPENSES!$H:$H,DEPENSES!$J:$J,'Rapport Bilan'!$C28,DEPENSES!$B:$B,'Rapport Bilan'!H$8) -> 0 | I28: =+SUMIFS(DEPENSES!$H:$H,DEPENSES!$J:$J,'Rapport Bilan'!$C28,DEPENSES!$B:$B,'Rapport Bilan'!I$8) -> 0 | J28: =+SUMIFS(DEPENSES!$H:$H,DEPENSES!$J:$J,'Rapport Bilan'!$C28,DEPENSES!$B:$B,'Rapport Bilan'!J$8) -> 0 | K28: =+SUMIFS(DEPENSES!$H:$H,DEPENSES!$J:$J,'Rapport Bilan'!$C28,DEPENSES!$B:$B,'Rapport Bilan'!K$8) -> 0 | L28: =+SUMIFS(DEPENSES!$H:$H,DEPENSES!$J:$J,'Rapport Bilan'!$C28,DEPENSES!$B:$B,'Rapport Bilan'!L$8) -> 0 | ... P28: =+SUMIFS(DEPENSES!$H:$H,DEPENSES!$J:$J,'Rapport Bilan'!$C28,DEPENSES!$B:$B,'Rapport Bilan'!P$8) -> 0 | Q28: =+SUM(E28:O28) -> 0 | R28: =+IFERROR(Q28/$Q$35,"")
C29: PUBLICITE, PUBLICATIONS, RELATIONS PUBLIQUES | E29: =+SUMIFS(DEPENSES!$H:$H,DEPENSES!$J:$J,'Rapport Bilan'!$C29,DEPENSES!$B:$B,'Rapport Bilan'!E$8) -> 0 | F29: =+SUMIFS(DEPENSES!$H:$H,DEPENSES!$J:$J,'Rapport Bilan'!$C29,DEPENSES!$B:$B,'Rapport Bilan'!F$8) -> 0 | G29: =+SUMIFS(DEPENSES!$H:$H,DEPENSES!$J:$J,'Rapport Bilan'!$C29,DEPENSES!$B:$B,'Rapport Bilan'!G$8) -> 0 | H29: =+SUMIFS(DEPENSES!$H:$H,DEPENSES!$J:$J,'Rapport Bilan'!$C29,DEPENSES!$B:$B,'Rapport Bilan'!H$8) -> 0 | I29: =+SUMIFS(DEPENSES!$H:$H,DEPENSES!$J:$J,'Rapport Bilan'!$C29,DEPENSES!$B:$B,'Rapport Bilan'!I$8) -> 0 | J29: =+SUMIFS(DEPENSES!$H:$H,DEPENSES!$J:$J,'Rapport Bilan'!$C29,DEPENSES!$B:$B,'Rapport Bilan'!J$8) -> 0 | K29: =+SUMIFS(DEPENSES!$H:$H,DEPENSES!$J:$J,'Rapport Bilan'!$C29,DEPENSES!$B:$B,'Rapport Bilan'!K$8) -> 0 | L29: =+SUMIFS(DEPENSES!$H:$H,DEPENSES!$J:$J,'Rapport Bilan'!$C29,DEPENSES!$B:$B,'Rapport Bilan'!L$8) -> 0 | ... P29: =+SUMIFS(DEPENSES!$H:$H,DEPENSES!$J:$J,'Rapport Bilan'!$C29,DEPENSES!$B:$B,'Rapport Bilan'!P$8) -> 0 | Q29: =+SUM(E29:O29) -> 0 | R29: =+IFERROR(Q29/$Q$35,"")
... C31: TELECOMMUNICATIONS | E31: =+SUMIFS(DEPENSES!$H:$H,DEPENSES!$J:$J,'Rapport Bilan'!$C31,DEPENSES!$B:$B,'Rapport Bilan'!E$8) -> 0 | F31: =+SUMIFS(DEPENSES!$H:$H,DEPENSES!$J:$J,'Rapport Bilan'!$C31,DEPENSES!$B:$B,'Rapport Bilan'!F$8) -> 0 | G31: =+SUMIFS(DEPENSES!$H:$H,DEPENSES!$J:$J,'Rapport Bilan'!$C31,DEPENSES!$B:$B,'Rapport Bilan'!G$8) -> 0 | H31: =+SUMIFS(DEPENSES!$H:$H,DEPENSES!$J:$J,'Rapport Bilan'!$C31,DEPENSES!$B:$B,'Rapport Bilan'!H$8) -> 0 | I31: =+SUMIFS(DEPENSES!$H:$H,DEPENSES!$J:$J,'Rapport Bilan'!$C31,DEPENSES!$B:$B,'Rapport Bilan'!I$8) -> 0 | J31: =+SUMIFS(DEPENSES!$H:$H,DEPENSES!$J:$J,'Rapport Bilan'!$C31,DEPENSES!$B:$B,'Rapport Bilan'!J$8) -> 0 | K31: =+SUMIFS(DEPENSES!$H:$H,DEPENSES!$J:$J,'Rapport Bilan'!$C31,DEPENSES!$B:$B,'Rapport Bilan'!K$8) -> 0 | L31: =+SUMIFS(DEPENSES!$H:$H,DEPENSES!$J:$J,'Rapport Bilan'!$C31,DEPENSES!$B:$B,'Rapport Bilan'!L$8) -> 0 | ... P31: =+SUMIFS(DEPENSES!$H:$H,DEPENSES!$J:$J,'Rapport Bilan'!$C31,DEPENSES!$B:$B,'Rapport Bilan'!P$8) -> 0 | Q31: =+SUM(E31:O31) -> 0 | R31: =+IFERROR(Q31/$Q$35,"")
C32: FRAIS BANCAIRES ET TRANSFERT | E32: =+SUMIFS(DEPENSES!$I:$I,DEPENSES!$B:$B,'Rapport Bilan'!E$8) -> 0 | F32: =+SUMIFS(DEPENSES!$I:$I,DEPENSES!$B:$B,'Rapport Bilan'!F$8) -> 0 | G32: =+SUMIFS(DEPENSES!$I:$I,DEPENSES!$B:$B,'Rapport Bilan'!G$8) -> 0 | H32: =+SUMIFS(DEPENSES!$I:$I,DEPENSES!$B:$B,'Rapport Bilan'!H$8) -> 0 | I32: =+SUMIFS(DEPENSES!$I:$I,DEPENSES!$B:$B,'Rapport Bilan'!I$8) -> 0 | J32: =+SUMIFS(DEPENSES!$I:$I,DEPENSES!$B:$B,'Rapport Bilan'!J$8) -> 0 | K32: =+SUMIFS(DEPENSES!$I:$I,DEPENSES!$B:$B,'Rapport Bilan'!K$8) -> 0 | L32: =+SUMIFS(DEPENSES!$I:$I,DEPENSES!$B:$B,'Rapport Bilan'!L$8) -> 0 | ... P32: =+SUMIFS(DEPENSES!$I:$I,DEPENSES!$B:$B,'Rapport Bilan'!P$8) -> 0 | Q32: =+SUM(E32:O32) -> 0 | R32: =+IFERROR(Q32/$Q$35,"")
C33: FRAIS DE FORMATION DU PERSONNEL | E33: =+SUMIFS(DEPENSES!$H:$H,DEPENSES!$J:$J,'Rapport Bilan'!$C33,DEPENSES!$B:$B,'Rapport Bilan'!E$8) -> 0 | F33: =+SUMIFS(DEPENSES!$H:$H,DEPENSES!$J:$J,'Rapport Bilan'!$C33,DEPENSES!$B:$B,'Rapport Bilan'!F$8) -> 0 | G33: =+SUMIFS(DEPENSES!$H:$H,DEPENSES!$J:$J,'Rapport Bilan'!$C33,DEPENSES!$B:$B,'Rapport Bilan'!G$8) -> 0 | H33: =+SUMIFS(DEPENSES!$H:$H,DEPENSES!$J:$J,'Rapport Bilan'!$C33,DEPENSES!$B:$B,'Rapport Bilan'!H$8) -> 0 | I33: =+SUMIFS(DEPENSES!$H:$H,DEPENSES!$J:$J,'Rapport Bilan'!$C33,DEPENSES!$B:$B,'Rapport Bilan'!I$8) -> 0 | J33: =+SUMIFS(DEPENSES!$H:$H,DEPENSES!$J:$J,'Rapport Bilan'!$C33,DEPENSES!$B:$B,'Rapport Bilan'!J$8) -> 0 | K33: =+SUMIFS(DEPENSES!$H:$H,DEPENSES!$J:$J,'Rapport Bilan'!$C33,DEPENSES!$B:$B,'Rapport Bilan'!K$8) -> 0 | L33: =+SUMIFS(DEPENSES!$H:$H,DEPENSES!$J:$J,'Rapport Bilan'!$C33,DEPENSES!$B:$B,'Rapport Bilan'!L$8) -> 0 | ... P33: =+SUMIFS(DEPENSES!$H:$H,DEPENSES!$J:$J,'Rapport Bilan'!$C33,DEPENSES!$B:$B,'Rapport Bilan'!P$8) -> 0 | Q33: =+SUM(E33:O33) -> 0 | R33: =+IFERROR(Q33/$Q$35,"")
C34: FRAIS DE RÉCEPTIONS - RESTAURATION | E34: =+SUMIFS(DEPENSES!$H:$H,DEPENSES!$J:$J,'Rapport Bilan'!$C34,DEPENSES!$B:$B,'Rapport Bilan'!E$8) -> 0 | F34: =+SUMIFS(DEPENSES!$H:$H,DEPENSES!$J:$J,'Rapport Bilan'!$C34,DEPENSES!$B:$B,'Rapport Bilan'!F$8) -> 0 | G34: =+SUMIFS(DEPENSES!$H:$H,DEPENSES!$J:$J,'Rapport Bilan'!$C34,DEPENSES!$B:$B,'Rapport Bilan'!G$8) -> 0 | H34: =+SUMIFS(DEPENSES!$H:$H,DEPENSES!$J:$J,'Rapport Bilan'!$C34,DEPENSES!$B:$B,'Rapport Bilan'!H$8) -> 0 | I34: =+SUMIFS(DEPENSES!$H:$H,DEPENSES!$J:$J,'Rapport Bilan'!$C34,DEPENSES!$B:$B,'Rapport Bilan'!I$8) -> 0 | J34: =+SUMIFS(DEPENSES!$H:$H,DEPENSES!$J:$J,'Rapport Bilan'!$C34,DEPENSES!$B:$B,'Rapport Bilan'!J$8) -> 0 | K34: =+SUMIFS(DEPENSES!$H:$H,DEPENSES!$J:$J,'Rapport Bilan'!$C34,DEPENSES!$B:$B,'Rapport Bilan'!K$8) -> 0 | L34: =+SUMIFS(DEPENSES!$H:$H,DEPENSES!$J:$J,'Rapport Bilan'!$C34,DEPENSES!$B:$B,'Rapport Bilan'!L$8) -> 0 | ... P34: =+SUMIFS(DEPENSES!$H:$H,DEPENSES!$J:$J,'Rapport Bilan'!$C34,DEPENSES!$B:$B,'Rapport Bilan'!P$8) -> 0 | Q34: =+SUM(E34:O34) -> 0 | R34: =+IFERROR(Q34/$Q$35,"")
C35: TOTAL CHARGE | E35: =+SUM(E18:E34) -> 0 | F35: =+SUM(F18:F34) -> 0 | G35: =+SUM(G18:G34) -> 0 | H35: =+SUM(H18:H34) -> 0 | I35: =+SUM(I18:I34) -> 0 | J35: =+SUM(J18:J34) -> 0 | K35: =+SUM(K18:K34) -> 0 | L35: =+SUM(L18:L34) -> 0 | ... P35: =+SUM(P18:P34) -> 0 | Q35: =SUM(Q18:Q34) -> 0 | R35: =+SUM(R18:R34) -> 0
C37: EXCÉDENT BRUT D'EXPLOITATION (EBE) | E37: =+E16-E35 -> 0 | F37: =+F16-F35 -> 0 | G37: =+G16-G35 -> 0 | H37: =+H16-H35 -> 0 | I37: =+I16-I35 -> 0 | J37: =+J16-J35 -> 0 | K37: =+K16-K35 -> 0 | L37: =+L16-L35 -> 0 | ... Q37: =+Q16-Q35 -> 0
C39: SOLDE CUMULE | E39: =+E37 -> 0 | F39: =+E39+F37 -> 0 | G39: =+F39+G37 -> 0 | H39: =+G39+H37 -> 0 | I39: =+H39+I37 -> 0 | J39: =+I39+J37 -> 0 | K39: =+J39+K37 -> 0 | L39: =+K39+L37 -> 0 | M39: =+L39+M37 -> 0 | ... P39: =+O39+P37 -> 0 | Q39: =+P39 -> 0
C42: LE SOLDE DU COMPTE À CE JOUR EST : | E42: =+Q39 -> 0
C44: EFFECTIF DES CLASSES ET REVENUS | E44: GARDERIE | F44: PS | G44: MS | H44: GS | I44: CI | J44: CP | K44: CE1 | L44: CE2 | M44: CM1 | N44: CM2 | O44: TOTAL
C45: EFFECTIF TOTAL DES ELEVES | E45: =+ENCAIS!D5 -> 0 | F45: =+ENCAIS!D6 -> 0 | G45: =+ENCAIS!D7 -> 0 | H45: =+ENCAIS!D8 -> 0 | I45: =+ENCAIS!D9 -> 0 | J45: =+ENCAIS!D10 -> 0 | K45: =+ENCAIS!D11 -> 0 | L45: =+ENCAIS!D12 -> 0 | M45: =+ENCAIS!D13 -> 0 | N45: =+ENCAIS!D14 -> 0 | O45: =+SUM(E45:N45) -> 0 | R45: CE2
C46: CHIFFRE D'AFFAIRE PAR CLASSE | E46: =+ENCAIS!R5 -> 0 | F46: =+ENCAIS!R6 -> 0 | G46: =+ENCAIS!R7 -> 0 | H46: =+ENCAIS!R8 -> 0 | I46: =+ENCAIS!R9 -> 0 | J46: =+ENCAIS!R10 -> 0 | K46: =+ENCAIS!R11 -> 0 | L46: =+ENCAIS!R12 -> 0 | M46: =+ENCAIS!R13 -> 0 | N46: =+ENCAIS!R14 -> 0 | O46: =+SUM(E46:N46) -> 0
C48: EFFECTIF TOTAL DU PERSONNEL : | E48: 10 | F48: Équipe pédagogique et personnel : 1 enseignant (CM1-CM2), 1 enseignante (CE1-CE2), 1 enseignant (CI-CP), 2 enseignantes (préscolaire), 1 enseignant d’arabe, 1 professeure d’anglais, 1 assistante stagiaire, 1 gardien, 1 femme de ménage
B51: M BODIAN | E51: COMMENTAIRE: Chiffre d'Affaires:4 978 000 (faible) ; Dépenses Totales:18 279 960 (élevées) ; Contribution des Actionnaires:13 412 000 (soutien essentiel) ; Arriérés de Location au 30 juin : 636 000 (à payer) et Restants de Salaires de juin : 250 000 (à payer). CONCLUSION: L'école fait face à un déséquilibre financier majeur, avec des dépenses dépassant largement les revenus. Les arriérés de location et les salaires non réglés aggravent la situation.
B52: PATHE
B53: D SAKHO

Sheet DEPENSES
C3: DATE OPERATION | D3: DATE PAIEMENT | E3: CANAL | F3: Num_Facture | G3: INTITULE | H3: MONTANT | I3: FRAIS TRANSFERT | J3: ITEMS
B4: =+EOMONTH(C4,0) -> 31
B5: =+EOMONTH(C5,0) -> 31
B6: =+EOMONTH(C6,0) -> 31
B7: =+EOMONTH(C7,0) -> 31
B8: =+EOMONTH(C8,0) -> 31
B9: =+EOMONTH(C9,0) -> 31
B10: =+EOMONTH(C10,0) -> 31
B11: =+EOMONTH(C11,0) -> 31 | Q11: =O2:Q11 -> 0
B12: =+EOMONTH(C12,0) -> 31
B13: =+EOMONTH(C13,0) -> 31
B14: =+EOMONTH(C14,0) -> 31
B15: =+EOMONTH(C15,0) -> 31
B16: =+EOMONTH(C16,0) -> 31
B17: =+EOMONTH(C17,0) -> 31
B18: =+EOMONTH(C18,0) -> 31
B19: =+EOMONTH(C19,0) -> 31
B20: =+EOMONTH(C20,0) -> 31
B21: =+EOMONTH(C21,0) -> 31
B22: =+EOMONTH(C22,0) -> 31
B23: =+EOMONTH(C23,0) -> 31
... B46: =+EOMONTH(C46,0) -> 31
C49: TOTAL | H49: =+SUM(H4:H48) -> 0 | I49: =+SUM(I4:I48) -> 0
